Traceback (most recent call last):
  File "/home/pi/bots/discord_bot/main.py", line 4, in <module>
    from mongoengine import *
ModuleNotFoundError: No module named 'mongoengine'
Traceback (most recent call last):
  File "/home/pi/bots/discord_bot/main.py", line 4, in <module>
    from mongoengine import *
ModuleNotFoundError: No module named 'mongoengine'
---------
 Chu pra
---------
It appears that you are using PRAW in an asynchronous environment.
It is strongly recommended to use Async PRAW: https://asyncpraw.readthedocs.io.
See https://praw.readthedocs.io/en/latest/getting_started/multiple_instances.html#discord-bots-and-asynchronous-environments for more info.

It appears that you are using PRAW in an asynchronous environment.
It is strongly recommended to use Async PRAW: https://asyncpraw.readthedocs.io.
See https://praw.readthedocs.io/en/latest/getting_started/multiple_instances.html#discord-bots-and-asynchronous-environments for more info.

It appears that you are using PRAW in an asynchronous environment.
It is strongly recommended to use Async PRAW: https://asyncpraw.readthedocs.io.
See https://praw.readthedocs.io/en/latest/getting_started/multiple_instances.html#discord-bots-and-asynchronous-environments for more info.

Ignoring exception in command reddit:
Traceback (most recent call last):
  File "/home/pi/.local/lib/python3.9/site-packages/discord/ext/commands/core.py", line 85, in wrapped
    ret = await coro(*args, **kwargs)
  File "/home/pi/bots/discord_bot/cogs/reddit.py", line 21, in reddit
    submission = next(x for x in submissions if not x.stickied)
  File "/home/pi/bots/discord_bot/cogs/reddit.py", line 21, in <genexpr>
    submission = next(x for x in submissions if not x.stickied)
  File "/home/pi/.local/lib/python3.9/site-packages/praw/models/listing/generator.py", line 63, in __next__
    self._next_batch()
  File "/home/pi/.local/lib/python3.9/site-packages/praw/models/listing/generator.py", line 89, in _next_batch
    self._listing = self._reddit.get(self.url, params=self.params)
  File "/home/pi/.local/lib/python3.9/site-packages/praw/util/deprecate_args.py", line 43, in wrapped
    return func(**dict(zip(_old_args, args)), **kwargs)
  File "/home/pi/.local/lib/python3.9/site-packages/praw/reddit.py", line 634, in get
    return self._objectify_request(method="GET", params=params, path=path)
  File "/home/pi/.local/lib/python3.9/site-packages/praw/reddit.py", line 739, in _objectify_request
    self.request(
  File "/home/pi/.local/lib/python3.9/site-packages/praw/util/deprecate_args.py", line 43, in wrapped
    return func(**dict(zip(_old_args, args)), **kwargs)
  File "/home/pi/.local/lib/python3.9/site-packages/praw/reddit.py", line 941, in request
    return self._core.request(
  File "/home/pi/.local/lib/python3.9/site-packages/prawcore/sessions.py", line 330, in request
    return self._request_with_retries(
  File "/home/pi/.local/lib/python3.9/site-packages/prawcore/sessions.py", line 266, in _request_with_retries
    raise self.STATUS_EXCEPTIONS[response.status_code](response)
prawcore.exceptions.NotFound: received 404 HTTP response

The above exception was the direct cause of the following exception:

Traceback (most recent call last):
  File "/home/pi/.local/lib/python3.9/site-packages/discord/ext/commands/bot.py", line 939, in invoke
    await ctx.command.invoke(ctx)
  File "/home/pi/.local/lib/python3.9/site-packages/discord/ext/commands/core.py", line 863, in invoke
    await injected(*ctx.args, **ctx.kwargs)
  File "/home/pi/.local/lib/python3.9/site-packages/discord/ext/commands/core.py", line 94, in wrapped
    raise CommandInvokeError(exc) from exc
discord.ext.commands.errors.CommandInvokeError: Command raised an exception: NotFound: received 404 HTTP response
It appears that you are using PRAW in an asynchronous environment.
It is strongly recommended to use Async PRAW: https://asyncpraw.readthedocs.io.
See https://praw.readthedocs.io/en/latest/getting_started/multiple_instances.html#discord-bots-and-asynchronous-environments for more info.

It appears that you are using PRAW in an asynchronous environment.
It is strongly recommended to use Async PRAW: https://asyncpraw.readthedocs.io.
See https://praw.readthedocs.io/en/latest/getting_started/multiple_instances.html#discord-bots-and-asynchronous-environments for more info.

It appears that you are using PRAW in an asynchronous environment.
It is strongly recommended to use Async PRAW: https://asyncpraw.readthedocs.io.
See https://praw.readthedocs.io/en/latest/getting_started/multiple_instances.html#discord-bots-and-asynchronous-environments for more info.

It appears that you are using PRAW in an asynchronous environment.
It is strongly recommended to use Async PRAW: https://asyncpraw.readthedocs.io.
See https://praw.readthedocs.io/en/latest/getting_started/multiple_instances.html#discord-bots-and-asynchronous-environments for more info.

It appears that you are using PRAW in an asynchronous environment.
It is strongly recommended to use Async PRAW: https://asyncpraw.readthedocs.io.
See https://praw.readthedocs.io/en/latest/getting_started/multiple_instances.html#discord-bots-and-asynchronous-environments for more info.

Ignoring exception in command reddit:
Traceback (most recent call last):
  File "/home/pi/.local/lib/python3.9/site-packages/discord/ext/commands/core.py", line 85, in wrapped
    ret = await coro(*args, **kwargs)
  File "/home/pi/bots/discord_bot/cogs/reddit.py", line 21, in reddit
    submission = next(x for x in submissions if not x.stickied)
  File "/home/pi/bots/discord_bot/cogs/reddit.py", line 21, in <genexpr>
    submission = next(x for x in submissions if not x.stickied)
  File "/home/pi/.local/lib/python3.9/site-packages/praw/models/listing/generator.py", line 63, in __next__
    self._next_batch()
  File "/home/pi/.local/lib/python3.9/site-packages/praw/models/listing/generator.py", line 89, in _next_batch
    self._listing = self._reddit.get(self.url, params=self.params)
  File "/home/pi/.local/lib/python3.9/site-packages/praw/util/deprecate_args.py", line 43, in wrapped
    return func(**dict(zip(_old_args, args)), **kwargs)
  File "/home/pi/.local/lib/python3.9/site-packages/praw/reddit.py", line 634, in get
    return self._objectify_request(method="GET", params=params, path=path)
  File "/home/pi/.local/lib/python3.9/site-packages/praw/reddit.py", line 739, in _objectify_request
    self.request(
  File "/home/pi/.local/lib/python3.9/site-packages/praw/util/deprecate_args.py", line 43, in wrapped
    return func(**dict(zip(_old_args, args)), **kwargs)
  File "/home/pi/.local/lib/python3.9/site-packages/praw/reddit.py", line 941, in request
    return self._core.request(
  File "/home/pi/.local/lib/python3.9/site-packages/prawcore/sessions.py", line 330, in request
    return self._request_with_retries(
  File "/home/pi/.local/lib/python3.9/site-packages/prawcore/sessions.py", line 266, in _request_with_retries
    raise self.STATUS_EXCEPTIONS[response.status_code](response)
prawcore.exceptions.Redirect: Redirect to /subreddits/search

The above exception was the direct cause of the following exception:

Traceback (most recent call last):
  File "/home/pi/.local/lib/python3.9/site-packages/discord/ext/commands/bot.py", line 939, in invoke
    await ctx.command.invoke(ctx)
  File "/home/pi/.local/lib/python3.9/site-packages/discord/ext/commands/core.py", line 863, in invoke
    await injected(*ctx.args, **ctx.kwargs)
  File "/home/pi/.local/lib/python3.9/site-packages/discord/ext/commands/core.py", line 94, in wrapped
    raise CommandInvokeError(exc) from exc
discord.ext.commands.errors.CommandInvokeError: Command raised an exception: Redirect: Redirect to /subreddits/search
It appears that you are using PRAW in an asynchronous environment.
It is strongly recommended to use Async PRAW: https://asyncpraw.readthedocs.io.
See https://praw.readthedocs.io/en/latest/getting_started/multiple_instances.html#discord-bots-and-asynchronous-environments for more info.

Ignoring exception in command insult:
Traceback (most recent call last):
  File "/home/pi/.local/lib/python3.9/site-packages/discord/ext/commands/core.py", line 85, in wrapped
    ret = await coro(*args, **kwargs)
  File "/home/pi/bots/discord_bot/cogs/memes.py", line 30, in insult
    insult = await get_mom_joke()
  File "/home/pi/bots/discord_bot/utils.py", line 37, in get_mom_joke
    insult = random.choice(list(jokes[random_category]))
  File "/usr/lib/python3.9/random.py", line 347, in choice
    return seq[self._randbelow(len(seq))]
IndexError: list index out of range

The above exception was the direct cause of the following exception:

Traceback (most recent call last):
  File "/home/pi/.local/lib/python3.9/site-packages/discord/ext/commands/bot.py", line 939, in invoke
    await ctx.command.invoke(ctx)
  File "/home/pi/.local/lib/python3.9/site-packages/discord/ext/commands/core.py", line 863, in invoke
    await injected(*ctx.args, **ctx.kwargs)
  File "/home/pi/.local/lib/python3.9/site-packages/discord/ext/commands/core.py", line 94, in wrapped
    raise CommandInvokeError(exc) from exc
discord.ext.commands.errors.CommandInvokeError: Command raised an exception: IndexError: list index out of range
Ignoring exception in command insult:
Traceback (most recent call last):
  File "/home/pi/.local/lib/python3.9/site-packages/discord/ext/commands/core.py", line 85, in wrapped
    ret = await coro(*args, **kwargs)
  File "/home/pi/bots/discord_bot/cogs/memes.py", line 30, in insult
    insult = await get_mom_joke()
  File "/home/pi/bots/discord_bot/utils.py", line 37, in get_mom_joke
    insult = random.choice(list(jokes[random_category]))
  File "/usr/lib/python3.9/random.py", line 347, in choice
    return seq[self._randbelow(len(seq))]
IndexError: list index out of range

The above exception was the direct cause of the following exception:

Traceback (most recent call last):
  File "/home/pi/.local/lib/python3.9/site-packages/discord/ext/commands/bot.py", line 939, in invoke
    await ctx.command.invoke(ctx)
  File "/home/pi/.local/lib/python3.9/site-packages/discord/ext/commands/core.py", line 863, in invoke
    await injected(*ctx.args, **ctx.kwargs)
  File "/home/pi/.local/lib/python3.9/site-packages/discord/ext/commands/core.py", line 94, in wrapped
    raise CommandInvokeError(exc) from exc
discord.ext.commands.errors.CommandInvokeError: Command raised an exception: IndexError: list index out of range
Ignoring exception in command insult:
Traceback (most recent call last):
  File "/home/pi/.local/lib/python3.9/site-packages/discord/ext/commands/core.py", line 85, in wrapped
    ret = await coro(*args, **kwargs)
  File "/home/pi/bots/discord_bot/cogs/memes.py", line 30, in insult
    insult = await get_mom_joke()
  File "/home/pi/bots/discord_bot/utils.py", line 37, in get_mom_joke
    insult = random.choice(list(jokes[random_category]))
  File "/usr/lib/python3.9/random.py", line 347, in choice
    return seq[self._randbelow(len(seq))]
IndexError: list index out of range

The above exception was the direct cause of the following exception:

Traceback (most recent call last):
  File "/home/pi/.local/lib/python3.9/site-packages/discord/ext/commands/bot.py", line 939, in invoke
    await ctx.command.invoke(ctx)
  File "/home/pi/.local/lib/python3.9/site-packages/discord/ext/commands/core.py", line 863, in invoke
    await injected(*ctx.args, **ctx.kwargs)
  File "/home/pi/.local/lib/python3.9/site-packages/discord/ext/commands/core.py", line 94, in wrapped
    raise CommandInvokeError(exc) from exc
discord.ext.commands.errors.CommandInvokeError: Command raised an exception: IndexError: list index out of range
Ignoring exception in command None:
discord.ext.commands.errors.CommandNotFound: Command "Rr" is not found
Ignoring exception in command None:
discord.ext.commands.errors.CommandNotFound: Command "rrr" is not found
Ignoring exception in command None:
discord.ext.commands.errors.CommandNotFound: Command "R" is not found
Ignoring exception in command None:
discord.ext.commands.errors.CommandNotFound: Command "r" is not found
Ignoring exception in command None:
discord.ext.commands.errors.CommandNotFound: Command "r" is not found
Ignoring exception in command None:
discord.ext.commands.errors.CommandNotFound: Command "r" is not found
---------
 Chu pra
---------
13quik joined Pernis
FrozenCheerios joined Pernis
Lord Corbin joined Pernis
Lord Corbin joined Pernis
Lord Corbin joined Pernis
Lord Corbin joined Pernis
Lord Corbin joined Pernis
Lord Corbin joined Pernis
Lord Corbin joined Pernis
Lord Corbin joined Pernis
Lord Corbin joined Pernis
Lord Corbin joined Pernis
Lord Corbin joined Pernis
Lord Corbin joined Pernis
Lord Corbin joined Pernis
Lord Corbin joined Pernis
Lord Corbin joined Pernis
Lord Corbin joined Pernis
13quik joined Pernis
FrozenCheerios joined Pernis
FrozenCheerios joined Pernis
Bot Green-bot joined Pernis
Lord Corbin joined Pernis
somethin else happened
13quik started streaming
somethin else happened
somethin else happened
13quik started streaming
groskhul joined Pernis
13quik joined Pernis
somethin else happened
groskhul started streaming
somethin else happened
somethin else happened
13quik started streaming
somethin else happened
groskhul started streaming
somethin else happened
somethin else happened
Lord Corbin joined Pernis
Lord Corbin joined Pernis
somethin else happened
somethin else happened
somethin else happened
somethin else happened
somethin else happened
somethin else happened
somethin else happened
somethin else happened
somethin else happened
somethin else happened
somethin else happened
somethin else happened
somethin else happened
somethin else happened
somethin else happened
somethin else happened
somethin else happened
somethin else happened
Bot StepBot joined Pernis
Traceback (most recent call last):
  File "/home/pi/.local/lib/python3.9/site-packages/discord/ext/commands/bot.py", line 606, in _load_from_module_spec
    spec.loader.exec_module(lib)
  File "<frozen importlib._bootstrap_external>", line 790, in exec_module
  File "<frozen importlib._bootstrap>", line 228, in _call_with_frames_removed
  File "/home/pi/bots/discord_bot/cogs/memes.py", line 4, in <module>
    from wallet import Wallet
  File "/home/pi/bots/discord_bot/wallet.py", line 5
    def create_wallet(user, money)
                                  ^
SyntaxError: invalid syntax

The above exception was the direct cause of the following exception:

Traceback (most recent call last):
  File "/home/pi/bots/discord_bot/main.py", line 17, in <module>
    bot.load_extension(f'cogs.{filename[:-3]}')
  File "/home/pi/.local/lib/python3.9/site-packages/discord/ext/commands/bot.py", line 678, in load_extension
    self._load_from_module_spec(spec, name)
  File "/home/pi/.local/lib/python3.9/site-packages/discord/ext/commands/bot.py", line 609, in _load_from_module_spec
    raise errors.ExtensionFailed(key, e) from e
discord.ext.commands.errors.ExtensionFailed: Extension 'cogs.memes' raised an error: SyntaxError: invalid syntax (wallet.py, line 5)
Traceback (most recent call last):
  File "/home/pi/.local/lib/python3.9/site-packages/discord/ext/commands/bot.py", line 606, in _load_from_module_spec
    spec.loader.exec_module(lib)
  File "<frozen importlib._bootstrap_external>", line 790, in exec_module
  File "<frozen importlib._bootstrap>", line 228, in _call_with_frames_removed
  File "/home/pi/bots/discord_bot/cogs/memes.py", line 4, in <module>
    from wallet import Wallet
  File "/home/pi/bots/discord_bot/wallet.py", line 5
    def create_wallet(user, money)
                                  ^
SyntaxError: invalid syntax

The above exception was the direct cause of the following exception:

Traceback (most recent call last):
  File "/home/pi/bots/discord_bot/main.py", line 17, in <module>
    bot.load_extension(f'cogs.{filename[:-3]}')
  File "/home/pi/.local/lib/python3.9/site-packages/discord/ext/commands/bot.py", line 678, in load_extension
    self._load_from_module_spec(spec, name)
  File "/home/pi/.local/lib/python3.9/site-packages/discord/ext/commands/bot.py", line 609, in _load_from_module_spec
    raise errors.ExtensionFailed(key, e) from e
discord.ext.commands.errors.ExtensionFailed: Extension 'cogs.memes' raised an error: SyntaxError: invalid syntax (wallet.py, line 5)
Traceback (most recent call last):
  File "/home/pi/.local/lib/python3.9/site-packages/discord/ext/commands/bot.py", line 606, in _load_from_module_spec
    spec.loader.exec_module(lib)
  File "<frozen importlib._bootstrap_external>", line 790, in exec_module
  File "<frozen importlib._bootstrap>", line 228, in _call_with_frames_removed
  File "/home/pi/bots/discord_bot/cogs/memes.py", line 4, in <module>
    from wallet import Wallet
  File "/home/pi/bots/discord_bot/wallet.py", line 5
    def create_wallet(user, money)
                                  ^
SyntaxError: invalid syntax

The above exception was the direct cause of the following exception:

Traceback (most recent call last):
  File "/home/pi/bots/discord_bot/main.py", line 17, in <module>
    bot.load_extension(f'cogs.{filename[:-3]}')
  File "/home/pi/.local/lib/python3.9/site-packages/discord/ext/commands/bot.py", line 678, in load_extension
    self._load_from_module_spec(spec, name)
  File "/home/pi/.local/lib/python3.9/site-packages/discord/ext/commands/bot.py", line 609, in _load_from_module_spec
    raise errors.ExtensionFailed(key, e) from e
discord.ext.commands.errors.ExtensionFailed: Extension 'cogs.memes' raised an error: SyntaxError: invalid syntax (wallet.py, line 5)
Ignoring exception in command None:
discord.ext.commands.errors.CommandNotFound: Command "cock" is not found
It appears that you are using PRAW in an asynchronous environment.
It is strongly recommended to use Async PRAW: https://asyncpraw.readthedocs.io.
See https://praw.readthedocs.io/en/latest/getting_started/multiple_instances.html#discord-bots-and-asynchronous-environments for more info.

It appears that you are using PRAW in an asynchronous environment.
It is strongly recommended to use Async PRAW: https://asyncpraw.readthedocs.io.
See https://praw.readthedocs.io/en/latest/getting_started/multiple_instances.html#discord-bots-and-asynchronous-environments for more info.

It appears that you are using PRAW in an asynchronous environment.
It is strongly recommended to use Async PRAW: https://asyncpraw.readthedocs.io.
See https://praw.readthedocs.io/en/latest/getting_started/multiple_instances.html#discord-bots-and-asynchronous-environments for more info.

---------
 Chu pra
---------
FrozenCheerios joined Pernis
13quik joined Pernis
somethin else happened
13quik started streaming
somethin else happened
FrozenCheerios started streaming
somethin else happened
somethin else happened
---------
 Chu pra
---------
somethin else happened
FrozenCheerios started streaming
somethin else happened
Ignoring exception in command rr:
Traceback (most recent call last):
  File "/home/pi/.local/lib/python3.9/site-packages/discord/ext/commands/core.py", line 85, in wrapped
    ret = await coro(*args, **kwargs)
  File "/home/pi/bots/discord_bot/cogs/games.py", line 58, in rr
    voice_channel = ctx.author.voice.channel
AttributeError: 'NoneType' object has no attribute 'channel'

The above exception was the direct cause of the following exception:

Traceback (most recent call last):
  File "/home/pi/.local/lib/python3.9/site-packages/discord/ext/commands/bot.py", line 939, in invoke
    await ctx.command.invoke(ctx)
  File "/home/pi/.local/lib/python3.9/site-packages/discord/ext/commands/core.py", line 863, in invoke
    await injected(*ctx.args, **ctx.kwargs)
  File "/home/pi/.local/lib/python3.9/site-packages/discord/ext/commands/core.py", line 94, in wrapped
    raise CommandInvokeError(exc) from exc
discord.ext.commands.errors.CommandInvokeError: Command raised an exception: AttributeError: 'NoneType' object has no attribute 'channel'
---------
 Chu pra
---------
622136882049974272
94939075546460160 Bryan Trottier 25000
95671589315543040 Hector-Fabre 25000
167753085337337858 Lord Corbin 25012
229436247121068032 crygened 25000
235825095119994891 JayPowaa 25000
258267042489171969 charlss32 25200
388902413358071819 13quik 25000
389820854311059457 FrozenCheerios 25005
554434511769698344 pascal le grand frère 25000
622136882049974272 groskhul 3500003
642836665198444554 David990807 25000
656158065737072650 Cosmiic_Pussy 25000
769630884495097896 prépuce désuet 25000
769706704098164747 poche de fréquence 25000
774421019595243521 Dan H 25000
774430494476730388 Miliki 25000
794809335284105276 XxTedBundyxX 25000
964321130443853924 marc-andre123 25000
It appears that you are using PRAW in an asynchronous environment.
It is strongly recommended to use Async PRAW: https://asyncpraw.readthedocs.io.
See https://praw.readthedocs.io/en/latest/getting_started/multiple_instances.html#discord-bots-and-asynchronous-environments for more info.

It appears that you are using PRAW in an asynchronous environment.
It is strongly recommended to use Async PRAW: https://asyncpraw.readthedocs.io.
See https://praw.readthedocs.io/en/latest/getting_started/multiple_instances.html#discord-bots-and-asynchronous-environments for more info.

It appears that you are using PRAW in an asynchronous environment.
It is strongly recommended to use Async PRAW: https://asyncpraw.readthedocs.io.
See https://praw.readthedocs.io/en/latest/getting_started/multiple_instances.html#discord-bots-and-asynchronous-environments for more info.

It appears that you are using PRAW in an asynchronous environment.
It is strongly recommended to use Async PRAW: https://asyncpraw.readthedocs.io.
See https://praw.readthedocs.io/en/latest/getting_started/multiple_instances.html#discord-bots-and-asynchronous-environments for more info.

---------
 Chu pra
---------
Lord Corbin joined Pernis
Task exception was never retrieved
future: <Task finished name='Task-1' coro=<Music.start_nodes() done, defined at /home/pi/.local/lib/python3.9/site-packages/dismusic/music.py:98> exception=AttributeError("'Bot' object has no attribute 'lavalink_nodes'")>
Traceback (most recent call last):
  File "/home/pi/.local/lib/python3.9/site-packages/dismusic/music.py", line 104, in start_nodes
    for config in self.bot.lavalink_nodes:
AttributeError: 'Bot' object has no attribute 'lavalink_nodes'
---------
 Chu pra
---------
FrozenCheerios joined Pernis
groskhul joined Pernis
somethin else happened
groskhul started streaming
Lord Corbin joined Pernis
groskhul joined Pernis
[youtube] jIQ6UV2onyI: Downloading webpage
---------
 Chu pra
---------
Bot StepBot joined Pernis
Exception in voice thread Thread-3
Traceback (most recent call last):
  File "/home/pi/.local/lib/python3.9/site-packages/discord/player.py", line 603, in run
    self._do_run()
  File "/home/pi/.local/lib/python3.9/site-packages/discord/player.py", line 596, in _do_run
    play_audio(data, encode=not self.source.is_opus())
  File "/home/pi/.local/lib/python3.9/site-packages/discord/voice_client.py", line 638, in send_audio_packet
    self.socket.sendto(packet, (self.endpoint_ip, self.voice_port))
TypeError: str, bytes or bytearray expected, not NoneType
[youtube] U06jlgpMtQs: Downloading webpage
Bot StepBot joined Pernis
Lord Corbin joined Pernis
FrozenCheerios joined Pernis
[tls @ 0x556fb5d690] Error in the pull function.
[https @ 0x556f940c90] Will reconnect at 1277952 in 0 second(s), error=Input/output error.
Ignoring exception in on_voice_state_update
Traceback (most recent call last):
  File "/home/pi/.local/lib/python3.9/site-packages/discord/client.py", line 343, in _run_event
    await coro(*args, **kwargs)
  File "/home/pi/bots/discord_bot/cogs/activities.py", line 60, in on_voice_state_update
    voice_channel = member.voice.channel
AttributeError: 'NoneType' object has no attribute 'channel'
Ignoring exception in on_voice_state_update
Traceback (most recent call last):
  File "/home/pi/.local/lib/python3.9/site-packages/discord/client.py", line 343, in _run_event
    await coro(*args, **kwargs)
  File "/home/pi/bots/discord_bot/cogs/activities.py", line 60, in on_voice_state_update
    voice_channel = member.voice.channel
AttributeError: 'NoneType' object has no attribute 'channel'
Ignoring exception in on_voice_state_update
Traceback (most recent call last):
  File "/home/pi/.local/lib/python3.9/site-packages/discord/client.py", line 343, in _run_event
    await coro(*args, **kwargs)
  File "/home/pi/bots/discord_bot/cogs/activities.py", line 61, in on_voice_state_update
    await voice_channel.connect()
  File "/home/pi/.local/lib/python3.9/site-packages/discord/abc.py", line 1274, in connect
    raise ClientException('Already connected to a voice channel.')
discord.errors.ClientException: Already connected to a voice channel.
[youtube] 9_o4_4fwbpU: Downloading webpage
---------
 Chu pra
---------
13quik joined Pernis
Bot StepBot joined Pernis
[youtube] 9_o4_4fwbpU: Downloading MPD manifest
Ignoring exception in on_voice_state_update
Traceback (most recent call last):
  File "/home/pi/.local/lib/python3.9/site-packages/discord/client.py", line 343, in _run_event
    await coro(*args, **kwargs)
  File "/home/pi/bots/discord_bot/cogs/activities.py", line 61, in on_voice_state_update
    await voice_channel.connect()
  File "/home/pi/.local/lib/python3.9/site-packages/discord/abc.py", line 1274, in connect
    raise ClientException('Already connected to a voice channel.')
discord.errors.ClientException: Already connected to a voice channel.
Ignoring exception in on_voice_state_update
Traceback (most recent call last):
  File "/home/pi/.local/lib/python3.9/site-packages/discord/client.py", line 343, in _run_event
    await coro(*args, **kwargs)
  File "/home/pi/bots/discord_bot/cogs/activities.py", line 60, in on_voice_state_update
    voice_channel = member.voice.channel
AttributeError: 'NoneType' object has no attribute 'channel'
Ignoring exception in on_voice_state_update
Traceback (most recent call last):
  File "/home/pi/.local/lib/python3.9/site-packages/discord/client.py", line 343, in _run_event
    await coro(*args, **kwargs)
  File "/home/pi/bots/discord_bot/cogs/activities.py", line 61, in on_voice_state_update
    await voice_channel.connect()
  File "/home/pi/.local/lib/python3.9/site-packages/discord/abc.py", line 1274, in connect
    raise ClientException('Already connected to a voice channel.')
discord.errors.ClientException: Already connected to a voice channel.
Ignoring exception in on_voice_state_update
Traceback (most recent call last):
  File "/home/pi/.local/lib/python3.9/site-packages/discord/client.py", line 343, in _run_event
    await coro(*args, **kwargs)
  File "/home/pi/bots/discord_bot/cogs/activities.py", line 60, in on_voice_state_update
    voice_channel = member.voice.channel
AttributeError: 'NoneType' object has no attribute 'channel'
Ignoring exception in on_voice_state_update
Traceback (most recent call last):
  File "/home/pi/.local/lib/python3.9/site-packages/discord/client.py", line 343, in _run_event
    await coro(*args, **kwargs)
  File "/home/pi/bots/discord_bot/cogs/activities.py", line 61, in on_voice_state_update
    await voice_channel.connect()
  File "/home/pi/.local/lib/python3.9/site-packages/discord/abc.py", line 1274, in connect
    raise ClientException('Already connected to a voice channel.')
discord.errors.ClientException: Already connected to a voice channel.
groskhul joined Pernis
groskhul joined Pernis
13quik joined Pernis
Ignoring exception in on_voice_state_update
Traceback (most recent call last):
  File "/home/pi/.local/lib/python3.9/site-packages/discord/client.py", line 343, in _run_event
    await coro(*args, **kwargs)
  File "/home/pi/bots/discord_bot/cogs/activities.py", line 22, in on_voice_state_update
    voice_channel = member.voice.channel
AttributeError: 'NoneType' object has no attribute 'channel'
ERROR: '' is not a valid URL. Set --default-search "ytsearch" (or run  youtube-dl "ytsearch:" ) to search YouTube
Ignoring exception in on_voice_state_update
Traceback (most recent call last):
  File "/home/pi/.local/lib/python3.9/site-packages/youtube_dl/YoutubeDL.py", line 815, in wrapper
    return func(self, *args, **kwargs)
  File "/home/pi/.local/lib/python3.9/site-packages/youtube_dl/YoutubeDL.py", line 836, in __extract_info
    ie_result = ie.extract(url)
  File "/home/pi/.local/lib/python3.9/site-packages/youtube_dl/extractor/common.py", line 534, in extract
    ie_result = self._real_extract(url)
  File "/home/pi/.local/lib/python3.9/site-packages/youtube_dl/extractor/generic.py", line 2361, in _real_extract
    raise ExtractorError(
youtube_dl.utils.ExtractorError: '' is not a valid URL. Set --default-search "ytsearch" (or run  youtube-dl "ytsearch:" ) to search YouTube

During handling of the above exception, another exception occurred:

Traceback (most recent call last):
  File "/home/pi/.local/lib/python3.9/site-packages/discord/client.py", line 343, in _run_event
    await coro(*args, **kwargs)
  File "/home/pi/bots/discord_bot/cogs/activities.py", line 80, in on_voice_state_update
    info = ydl.extract_info(url, download=False)
  File "/home/pi/.local/lib/python3.9/site-packages/youtube_dl/YoutubeDL.py", line 808, in extract_info
    return self.__extract_info(url, ie, download, extra_info, process)
  File "/home/pi/.local/lib/python3.9/site-packages/youtube_dl/YoutubeDL.py", line 824, in wrapper
    self.report_error(compat_str(e), e.format_traceback())
  File "/home/pi/.local/lib/python3.9/site-packages/youtube_dl/YoutubeDL.py", line 628, in report_error
    self.trouble(error_message, tb)
  File "/home/pi/.local/lib/python3.9/site-packages/youtube_dl/YoutubeDL.py", line 598, in trouble
    raise DownloadError(message, exc_info)
youtube_dl.utils.DownloadError: ERROR: '' is not a valid URL. Set --default-search "ytsearch" (or run  youtube-dl "ytsearch:" ) to search YouTube
[youtube] _p2ymy8481Q: Downloading webpage
---------
 Chu pra
---------
somethin else happened
groskhul started streaming
somethin else happened
Bot StepBot joined Pernis
Ignoring exception in on_voice_state_update
Traceback (most recent call last):
  File "/home/pi/.local/lib/python3.9/site-packages/discord/client.py", line 343, in _run_event
    await coro(*args, **kwargs)
  File "/home/pi/bots/discord_bot/cogs/activities.py", line 22, in on_voice_state_update
    voice_channel = member.voice.channel
AttributeError: 'NoneType' object has no attribute 'channel'
Ignoring exception in on_voice_state_update
Traceback (most recent call last):
  File "/home/pi/.local/lib/python3.9/site-packages/discord/client.py", line 343, in _run_event
    await coro(*args, **kwargs)
  File "/home/pi/bots/discord_bot/cogs/activities.py", line 22, in on_voice_state_update
    voice_channel = member.voice.channel
AttributeError: 'NoneType' object has no attribute 'channel'
[tls @ 0x55981c5f00] Error in the pull function.
[https @ 0x559820fc80] Will reconnect at 1884160 in 0 second(s), error=Input/output error.
Ignoring exception in on_voice_state_update
Traceback (most recent call last):
  File "/home/pi/.local/lib/python3.9/site-packages/discord/client.py", line 343, in _run_event
    await coro(*args, **kwargs)
  File "/home/pi/bots/discord_bot/cogs/activities.py", line 22, in on_voice_state_update
    voice_channel = member.voice.channel
AttributeError: 'NoneType' object has no attribute 'channel'
ERROR: '' is not a valid URL. Set --default-search "ytsearch" (or run  youtube-dl "ytsearch:" ) to search YouTube
Ignoring exception in on_voice_state_update
Traceback (most recent call last):
  File "/home/pi/.local/lib/python3.9/site-packages/youtube_dl/YoutubeDL.py", line 815, in wrapper
    return func(self, *args, **kwargs)
  File "/home/pi/.local/lib/python3.9/site-packages/youtube_dl/YoutubeDL.py", line 836, in __extract_info
    ie_result = ie.extract(url)
  File "/home/pi/.local/lib/python3.9/site-packages/youtube_dl/extractor/common.py", line 534, in extract
    ie_result = self._real_extract(url)
  File "/home/pi/.local/lib/python3.9/site-packages/youtube_dl/extractor/generic.py", line 2361, in _real_extract
    raise ExtractorError(
youtube_dl.utils.ExtractorError: '' is not a valid URL. Set --default-search "ytsearch" (or run  youtube-dl "ytsearch:" ) to search YouTube

During handling of the above exception, another exception occurred:

Traceback (most recent call last):
  File "/home/pi/.local/lib/python3.9/site-packages/discord/client.py", line 343, in _run_event
    await coro(*args, **kwargs)
  File "/home/pi/bots/discord_bot/cogs/activities.py", line 80, in on_voice_state_update
    info = ydl.extract_info(url, download=False)
  File "/home/pi/.local/lib/python3.9/site-packages/youtube_dl/YoutubeDL.py", line 808, in extract_info
    return self.__extract_info(url, ie, download, extra_info, process)
  File "/home/pi/.local/lib/python3.9/site-packages/youtube_dl/YoutubeDL.py", line 824, in wrapper
    self.report_error(compat_str(e), e.format_traceback())
  File "/home/pi/.local/lib/python3.9/site-packages/youtube_dl/YoutubeDL.py", line 628, in report_error
    self.trouble(error_message, tb)
  File "/home/pi/.local/lib/python3.9/site-packages/youtube_dl/YoutubeDL.py", line 598, in trouble
    raise DownloadError(message, exc_info)
youtube_dl.utils.DownloadError: ERROR: '' is not a valid URL. Set --default-search "ytsearch" (or run  youtube-dl "ytsearch:" ) to search YouTube
[youtube] wrdK57qgNqA: Downloading webpage
FrozenCheerios joined Pernis
Bot StepBot joined Pernis
[youtube] wrdK57qgNqA: Downloading player 5784b7e4
Ignoring exception in on_voice_state_update
Traceback (most recent call last):
  File "/home/pi/.local/lib/python3.9/site-packages/discord/client.py", line 343, in _run_event
    await coro(*args, **kwargs)
  File "/home/pi/bots/discord_bot/cogs/activities.py", line 22, in on_voice_state_update
    voice_channel = member.voice.channel
AttributeError: 'NoneType' object has no attribute 'channel'
Ignoring exception in on_voice_state_update
Traceback (most recent call last):
  File "/home/pi/.local/lib/python3.9/site-packages/discord/client.py", line 343, in _run_event
    await coro(*args, **kwargs)
  File "/home/pi/bots/discord_bot/cogs/activities.py", line 22, in on_voice_state_update
    voice_channel = member.voice.channel
AttributeError: 'NoneType' object has no attribute 'channel'
[youtube] wrdK57qgNqA: Downloading webpage
FrozenCheerios joined Pernis
Ignoring exception in on_voice_state_update
Traceback (most recent call last):
  File "/home/pi/.local/lib/python3.9/site-packages/discord/client.py", line 343, in _run_event
    await coro(*args, **kwargs)
  File "/home/pi/bots/discord_bot/cogs/activities.py", line 84, in on_voice_state_update
    vc.play(source)
  File "/home/pi/.local/lib/python3.9/site-packages/discord/voice_client.py", line 555, in play
    raise ClientException('Not connected to voice.')
discord.errors.ClientException: Not connected to voice.
ERROR: '' is not a valid URL. Set --default-search "ytsearch" (or run  youtube-dl "ytsearch:" ) to search YouTube
Ignoring exception in on_voice_state_update
Traceback (most recent call last):
  File "/home/pi/.local/lib/python3.9/site-packages/youtube_dl/YoutubeDL.py", line 815, in wrapper
    return func(self, *args, **kwargs)
  File "/home/pi/.local/lib/python3.9/site-packages/youtube_dl/YoutubeDL.py", line 836, in __extract_info
    ie_result = ie.extract(url)
  File "/home/pi/.local/lib/python3.9/site-packages/youtube_dl/extractor/common.py", line 534, in extract
    ie_result = self._real_extract(url)
  File "/home/pi/.local/lib/python3.9/site-packages/youtube_dl/extractor/generic.py", line 2361, in _real_extract
    raise ExtractorError(
youtube_dl.utils.ExtractorError: '' is not a valid URL. Set --default-search "ytsearch" (or run  youtube-dl "ytsearch:" ) to search YouTube

During handling of the above exception, another exception occurred:

Traceback (most recent call last):
  File "/home/pi/.local/lib/python3.9/site-packages/discord/client.py", line 343, in _run_event
    await coro(*args, **kwargs)
  File "/home/pi/bots/discord_bot/cogs/activities.py", line 80, in on_voice_state_update
    info = ydl.extract_info(url, download=False)
  File "/home/pi/.local/lib/python3.9/site-packages/youtube_dl/YoutubeDL.py", line 808, in extract_info
    return self.__extract_info(url, ie, download, extra_info, process)
  File "/home/pi/.local/lib/python3.9/site-packages/youtube_dl/YoutubeDL.py", line 824, in wrapper
    self.report_error(compat_str(e), e.format_traceback())
  File "/home/pi/.local/lib/python3.9/site-packages/youtube_dl/YoutubeDL.py", line 628, in report_error
    self.trouble(error_message, tb)
  File "/home/pi/.local/lib/python3.9/site-packages/youtube_dl/YoutubeDL.py", line 598, in trouble
    raise DownloadError(message, exc_info)
youtube_dl.utils.DownloadError: ERROR: '' is not a valid URL. Set --default-search "ytsearch" (or run  youtube-dl "ytsearch:" ) to search YouTube
[youtube] 9_o4_4fwbpU: Downloading webpage
622136882049974272 groskhul 27000
388902413358071819 13quik 18500
94939075546460160 Bryan Trottier 25000
95671589315543040 Hector-Fabre 25000
167753085337337858 Lord Corbin 25000
229436247121068032 crygened 25000
235825095119994891 JayPowaa 25000
258267042489171969 charlss32 25000
389820854311059457 FrozenCheerios 25000
554434511769698344 pascal le grand frère 25000
642836665198444554 David990807 25000
656158065737072650 Cosmiic_Pussy 25000
769630884495097896 prépuce désuet 25000
769706704098164747 poche de fréquence 25000
774421019595243521 Dan H 25000
774430494476730388 Miliki 25000
794809335284105276 XxTedBundyxX 25000
964321130443853924 marc-andre123 25000
13quik joined Pernis
Bot StepBot joined Pernis
[youtube] 9_o4_4fwbpU: Downloading MPD manifest
[youtube] 9_o4_4fwbpU: Downloading webpage
somethin else happened
13quik started streaming
somethin else happened
[youtube] 9_o4_4fwbpU: Downloading MPD manifest
Ignoring exception in on_voice_state_update
Traceback (most recent call last):
  File "/home/pi/.local/lib/python3.9/site-packages/discord/client.py", line 343, in _run_event
    await coro(*args, **kwargs)
  File "/home/pi/bots/discord_bot/cogs/activities.py", line 22, in on_voice_state_update
    voice_channel = member.voice.channel
AttributeError: 'NoneType' object has no attribute 'channel'
[youtube] wrdK57qgNqA: Downloading webpage
somethin else happened
13quik started streaming
FrozenCheerios joined Pernis
[tls @ 0x55ac48ff00] Error in the pull function.
[https @ 0x55ac4d9c80] Will reconnect at 1179648 in 0 second(s), error=Input/output error.
Ignoring exception in on_voice_state_update
Traceback (most recent call last):
  File "/home/pi/.local/lib/python3.9/site-packages/discord/client.py", line 343, in _run_event
    await coro(*args, **kwargs)
  File "/home/pi/bots/discord_bot/cogs/activities.py", line 22, in on_voice_state_update
    voice_channel = member.voice.channel
AttributeError: 'NoneType' object has no attribute 'channel'
ERROR: '' is not a valid URL. Set --default-search "ytsearch" (or run  youtube-dl "ytsearch:" ) to search YouTube
Ignoring exception in on_voice_state_update
Traceback (most recent call last):
  File "/home/pi/.local/lib/python3.9/site-packages/youtube_dl/YoutubeDL.py", line 815, in wrapper
    return func(self, *args, **kwargs)
  File "/home/pi/.local/lib/python3.9/site-packages/youtube_dl/YoutubeDL.py", line 836, in __extract_info
    ie_result = ie.extract(url)
  File "/home/pi/.local/lib/python3.9/site-packages/youtube_dl/extractor/common.py", line 534, in extract
    ie_result = self._real_extract(url)
  File "/home/pi/.local/lib/python3.9/site-packages/youtube_dl/extractor/generic.py", line 2361, in _real_extract
    raise ExtractorError(
youtube_dl.utils.ExtractorError: '' is not a valid URL. Set --default-search "ytsearch" (or run  youtube-dl "ytsearch:" ) to search YouTube

During handling of the above exception, another exception occurred:

Traceback (most recent call last):
  File "/home/pi/.local/lib/python3.9/site-packages/discord/client.py", line 343, in _run_event
    await coro(*args, **kwargs)
  File "/home/pi/bots/discord_bot/cogs/activities.py", line 80, in on_voice_state_update
    info = ydl.extract_info(url, download=False)
  File "/home/pi/.local/lib/python3.9/site-packages/youtube_dl/YoutubeDL.py", line 808, in extract_info
    return self.__extract_info(url, ie, download, extra_info, process)
  File "/home/pi/.local/lib/python3.9/site-packages/youtube_dl/YoutubeDL.py", line 824, in wrapper
    self.report_error(compat_str(e), e.format_traceback())
  File "/home/pi/.local/lib/python3.9/site-packages/youtube_dl/YoutubeDL.py", line 628, in report_error
    self.trouble(error_message, tb)
  File "/home/pi/.local/lib/python3.9/site-packages/youtube_dl/YoutubeDL.py", line 598, in trouble
    raise DownloadError(message, exc_info)
youtube_dl.utils.DownloadError: ERROR: '' is not a valid URL. Set --default-search "ytsearch" (or run  youtube-dl "ytsearch:" ) to search YouTube
[youtube] 9_o4_4fwbpU: Downloading webpage
Bot StepBot joined Pernis
somethin else happened
[youtube] 9_o4_4fwbpU: Downloading MPD manifest
Ignoring exception in on_voice_state_update
Traceback (most recent call last):
  File "/home/pi/.local/lib/python3.9/site-packages/discord/client.py", line 343, in _run_event
    await coro(*args, **kwargs)
  File "/home/pi/bots/discord_bot/cogs/activities.py", line 22, in on_voice_state_update
    voice_channel = member.voice.channel
AttributeError: 'NoneType' object has no attribute 'channel'
Ignoring exception in on_voice_state_update
Traceback (most recent call last):
  File "/home/pi/.local/lib/python3.9/site-packages/discord/client.py", line 343, in _run_event
    await coro(*args, **kwargs)
  File "/home/pi/bots/discord_bot/cogs/activities.py", line 22, in on_voice_state_update
    voice_channel = member.voice.channel
AttributeError: 'NoneType' object has no attribute 'channel'
It appears that you are using PRAW in an asynchronous environment.
It is strongly recommended to use Async PRAW: https://asyncpraw.readthedocs.io.
See https://praw.readthedocs.io/en/latest/getting_started/multiple_instances.html#discord-bots-and-asynchronous-environments for more info.

Ignoring exception in command None:
discord.ext.commands.errors.CommandNotFound: Command "hentai" is not found
It appears that you are using PRAW in an asynchronous environment.
It is strongly recommended to use Async PRAW: https://asyncpraw.readthedocs.io.
See https://praw.readthedocs.io/en/latest/getting_started/multiple_instances.html#discord-bots-and-asynchronous-environments for more info.

Ignoring exception in command reddit:
Traceback (most recent call last):
  File "/home/pi/.local/lib/python3.9/site-packages/discord/ext/commands/core.py", line 85, in wrapped
    ret = await coro(*args, **kwargs)
  File "/home/pi/bots/discord_bot/cogs/reddit.py", line 21, in reddit
    submission = next(x for x in submissions if not x.stickied)
  File "/home/pi/bots/discord_bot/cogs/reddit.py", line 21, in <genexpr>
    submission = next(x for x in submissions if not x.stickied)
  File "/home/pi/.local/lib/python3.9/site-packages/praw/models/listing/generator.py", line 63, in __next__
    self._next_batch()
  File "/home/pi/.local/lib/python3.9/site-packages/praw/models/listing/generator.py", line 89, in _next_batch
    self._listing = self._reddit.get(self.url, params=self.params)
  File "/home/pi/.local/lib/python3.9/site-packages/praw/util/deprecate_args.py", line 43, in wrapped
    return func(**dict(zip(_old_args, args)), **kwargs)
  File "/home/pi/.local/lib/python3.9/site-packages/praw/reddit.py", line 634, in get
    return self._objectify_request(method="GET", params=params, path=path)
  File "/home/pi/.local/lib/python3.9/site-packages/praw/reddit.py", line 739, in _objectify_request
    self.request(
  File "/home/pi/.local/lib/python3.9/site-packages/praw/util/deprecate_args.py", line 43, in wrapped
    return func(**dict(zip(_old_args, args)), **kwargs)
  File "/home/pi/.local/lib/python3.9/site-packages/praw/reddit.py", line 941, in request
    return self._core.request(
  File "/home/pi/.local/lib/python3.9/site-packages/prawcore/sessions.py", line 330, in request
    return self._request_with_retries(
  File "/home/pi/.local/lib/python3.9/site-packages/prawcore/sessions.py", line 266, in _request_with_retries
    raise self.STATUS_EXCEPTIONS[response.status_code](response)
prawcore.exceptions.NotFound: received 404 HTTP response

The above exception was the direct cause of the following exception:

Traceback (most recent call last):
  File "/home/pi/.local/lib/python3.9/site-packages/discord/ext/commands/bot.py", line 939, in invoke
    await ctx.command.invoke(ctx)
  File "/home/pi/.local/lib/python3.9/site-packages/discord/ext/commands/core.py", line 863, in invoke
    await injected(*ctx.args, **ctx.kwargs)
  File "/home/pi/.local/lib/python3.9/site-packages/discord/ext/commands/core.py", line 94, in wrapped
    raise CommandInvokeError(exc) from exc
discord.ext.commands.errors.CommandInvokeError: Command raised an exception: NotFound: received 404 HTTP response
It appears that you are using PRAW in an asynchronous environment.
It is strongly recommended to use Async PRAW: https://asyncpraw.readthedocs.io.
See https://praw.readthedocs.io/en/latest/getting_started/multiple_instances.html#discord-bots-and-asynchronous-environments for more info.

It appears that you are using PRAW in an asynchronous environment.
It is strongly recommended to use Async PRAW: https://asyncpraw.readthedocs.io.
See https://praw.readthedocs.io/en/latest/getting_started/multiple_instances.html#discord-bots-and-asynchronous-environments for more info.

It appears that you are using PRAW in an asynchronous environment.
It is strongly recommended to use Async PRAW: https://asyncpraw.readthedocs.io.
See https://praw.readthedocs.io/en/latest/getting_started/multiple_instances.html#discord-bots-and-asynchronous-environments for more info.

It appears that you are using PRAW in an asynchronous environment.
It is strongly recommended to use Async PRAW: https://asyncpraw.readthedocs.io.
See https://praw.readthedocs.io/en/latest/getting_started/multiple_instances.html#discord-bots-and-asynchronous-environments for more info.

It appears that you are using PRAW in an asynchronous environment.
It is strongly recommended to use Async PRAW: https://asyncpraw.readthedocs.io.
See https://praw.readthedocs.io/en/latest/getting_started/multiple_instances.html#discord-bots-and-asynchronous-environments for more info.

Ignoring exception in command reddit:
Traceback (most recent call last):
  File "/home/pi/.local/lib/python3.9/site-packages/discord/ext/commands/core.py", line 85, in wrapped
    ret = await coro(*args, **kwargs)
  File "/home/pi/bots/discord_bot/cogs/reddit.py", line 21, in reddit
    submission = next(x for x in submissions if not x.stickied)
  File "/home/pi/bots/discord_bot/cogs/reddit.py", line 21, in <genexpr>
    submission = next(x for x in submissions if not x.stickied)
  File "/home/pi/.local/lib/python3.9/site-packages/praw/models/listing/generator.py", line 63, in __next__
    self._next_batch()
  File "/home/pi/.local/lib/python3.9/site-packages/praw/models/listing/generator.py", line 89, in _next_batch
    self._listing = self._reddit.get(self.url, params=self.params)
  File "/home/pi/.local/lib/python3.9/site-packages/praw/util/deprecate_args.py", line 43, in wrapped
    return func(**dict(zip(_old_args, args)), **kwargs)
  File "/home/pi/.local/lib/python3.9/site-packages/praw/reddit.py", line 634, in get
    return self._objectify_request(method="GET", params=params, path=path)
  File "/home/pi/.local/lib/python3.9/site-packages/praw/reddit.py", line 739, in _objectify_request
    self.request(
  File "/home/pi/.local/lib/python3.9/site-packages/praw/util/deprecate_args.py", line 43, in wrapped
    return func(**dict(zip(_old_args, args)), **kwargs)
  File "/home/pi/.local/lib/python3.9/site-packages/praw/reddit.py", line 941, in request
    return self._core.request(
  File "/home/pi/.local/lib/python3.9/site-packages/prawcore/sessions.py", line 330, in request
    return self._request_with_retries(
  File "/home/pi/.local/lib/python3.9/site-packages/prawcore/sessions.py", line 266, in _request_with_retries
    raise self.STATUS_EXCEPTIONS[response.status_code](response)
prawcore.exceptions.Forbidden: received 403 HTTP response

The above exception was the direct cause of the following exception:

Traceback (most recent call last):
  File "/home/pi/.local/lib/python3.9/site-packages/discord/ext/commands/bot.py", line 939, in invoke
    await ctx.command.invoke(ctx)
  File "/home/pi/.local/lib/python3.9/site-packages/discord/ext/commands/core.py", line 863, in invoke
    await injected(*ctx.args, **ctx.kwargs)
  File "/home/pi/.local/lib/python3.9/site-packages/discord/ext/commands/core.py", line 94, in wrapped
    raise CommandInvokeError(exc) from exc
discord.ext.commands.errors.CommandInvokeError: Command raised an exception: Forbidden: received 403 HTTP response
It appears that you are using PRAW in an asynchronous environment.
It is strongly recommended to use Async PRAW: https://asyncpraw.readthedocs.io.
See https://praw.readthedocs.io/en/latest/getting_started/multiple_instances.html#discord-bots-and-asynchronous-environments for more info.

It appears that you are using PRAW in an asynchronous environment.
It is strongly recommended to use Async PRAW: https://asyncpraw.readthedocs.io.
See https://praw.readthedocs.io/en/latest/getting_started/multiple_instances.html#discord-bots-and-asynchronous-environments for more info.

Ignoring exception in command reddit:
Traceback (most recent call last):
  File "/home/pi/bots/discord_bot/cogs/reddit.py", line 21, in reddit
    submission = next(x for x in submissions if not x.stickied)
StopIteration

The above exception was the direct cause of the following exception:

Traceback (most recent call last):
  File "/home/pi/.local/lib/python3.9/site-packages/discord/ext/commands/core.py", line 85, in wrapped
    ret = await coro(*args, **kwargs)
RuntimeError: coroutine raised StopIteration

The above exception was the direct cause of the following exception:

Traceback (most recent call last):
  File "/home/pi/.local/lib/python3.9/site-packages/discord/ext/commands/bot.py", line 939, in invoke
    await ctx.command.invoke(ctx)
  File "/home/pi/.local/lib/python3.9/site-packages/discord/ext/commands/core.py", line 863, in invoke
    await injected(*ctx.args, **ctx.kwargs)
  File "/home/pi/.local/lib/python3.9/site-packages/discord/ext/commands/core.py", line 94, in wrapped
    raise CommandInvokeError(exc) from exc
discord.ext.commands.errors.CommandInvokeError: Command raised an exception: RuntimeError: coroutine raised StopIteration
It appears that you are using PRAW in an asynchronous environment.
It is strongly recommended to use Async PRAW: https://asyncpraw.readthedocs.io.
See https://praw.readthedocs.io/en/latest/getting_started/multiple_instances.html#discord-bots-and-asynchronous-environments for more info.

Ignoring exception in command reddit:
Traceback (most recent call last):
  File "/home/pi/bots/discord_bot/cogs/reddit.py", line 21, in reddit
    submission = next(x for x in submissions if not x.stickied)
StopIteration

The above exception was the direct cause of the following exception:

Traceback (most recent call last):
  File "/home/pi/.local/lib/python3.9/site-packages/discord/ext/commands/core.py", line 85, in wrapped
    ret = await coro(*args, **kwargs)
RuntimeError: coroutine raised StopIteration

The above exception was the direct cause of the following exception:

Traceback (most recent call last):
  File "/home/pi/.local/lib/python3.9/site-packages/discord/ext/commands/bot.py", line 939, in invoke
    await ctx.command.invoke(ctx)
  File "/home/pi/.local/lib/python3.9/site-packages/discord/ext/commands/core.py", line 863, in invoke
    await injected(*ctx.args, **ctx.kwargs)
  File "/home/pi/.local/lib/python3.9/site-packages/discord/ext/commands/core.py", line 94, in wrapped
    raise CommandInvokeError(exc) from exc
discord.ext.commands.errors.CommandInvokeError: Command raised an exception: RuntimeError: coroutine raised StopIteration
It appears that you are using PRAW in an asynchronous environment.
It is strongly recommended to use Async PRAW: https://asyncpraw.readthedocs.io.
See https://praw.readthedocs.io/en/latest/getting_started/multiple_instances.html#discord-bots-and-asynchronous-environments for more info.

Ignoring exception in command reddit:
Traceback (most recent call last):
  File "/home/pi/bots/discord_bot/cogs/reddit.py", line 21, in reddit
    submission = next(x for x in submissions if not x.stickied)
StopIteration

The above exception was the direct cause of the following exception:

Traceback (most recent call last):
  File "/home/pi/.local/lib/python3.9/site-packages/discord/ext/commands/core.py", line 85, in wrapped
    ret = await coro(*args, **kwargs)
RuntimeError: coroutine raised StopIteration

The above exception was the direct cause of the following exception:

Traceback (most recent call last):
  File "/home/pi/.local/lib/python3.9/site-packages/discord/ext/commands/bot.py", line 939, in invoke
    await ctx.command.invoke(ctx)
  File "/home/pi/.local/lib/python3.9/site-packages/discord/ext/commands/core.py", line 863, in invoke
    await injected(*ctx.args, **ctx.kwargs)
  File "/home/pi/.local/lib/python3.9/site-packages/discord/ext/commands/core.py", line 94, in wrapped
    raise CommandInvokeError(exc) from exc
discord.ext.commands.errors.CommandInvokeError: Command raised an exception: RuntimeError: coroutine raised StopIteration
It appears that you are using PRAW in an asynchronous environment.
It is strongly recommended to use Async PRAW: https://asyncpraw.readthedocs.io.
See https://praw.readthedocs.io/en/latest/getting_started/multiple_instances.html#discord-bots-and-asynchronous-environments for more info.

It appears that you are using PRAW in an asynchronous environment.
It is strongly recommended to use Async PRAW: https://asyncpraw.readthedocs.io.
See https://praw.readthedocs.io/en/latest/getting_started/multiple_instances.html#discord-bots-and-asynchronous-environments for more info.

[youtube] _p2ymy8481Q: Downloading webpage
groskhul joined Pernis
[youtube] _p2ymy8481Q: Downloading player 240bde48
Ignoring exception in on_voice_state_update
Traceback (most recent call last):
  File "/home/pi/.local/lib/python3.9/site-packages/discord/client.py", line 343, in _run_event
    await coro(*args, **kwargs)
  File "/home/pi/bots/discord_bot/cogs/activities.py", line 22, in on_voice_state_update
    voice_channel = member.voice.channel
AttributeError: 'NoneType' object has no attribute 'channel'
[tls @ 0x5598ee8f00] Error in the pull function.
[https @ 0x5598f32c90] Will reconnect at 1949696 in 0 second(s), error=Input/output error.
ERROR: '' is not a valid URL. Set --default-search "ytsearch" (or run  youtube-dl "ytsearch:" ) to search YouTube
Ignoring exception in on_voice_state_update
Traceback (most recent call last):
  File "/home/pi/.local/lib/python3.9/site-packages/youtube_dl/YoutubeDL.py", line 815, in wrapper
    return func(self, *args, **kwargs)
  File "/home/pi/.local/lib/python3.9/site-packages/youtube_dl/YoutubeDL.py", line 836, in __extract_info
    ie_result = ie.extract(url)
  File "/home/pi/.local/lib/python3.9/site-packages/youtube_dl/extractor/common.py", line 534, in extract
    ie_result = self._real_extract(url)
  File "/home/pi/.local/lib/python3.9/site-packages/youtube_dl/extractor/generic.py", line 2361, in _real_extract
    raise ExtractorError(
youtube_dl.utils.ExtractorError: '' is not a valid URL. Set --default-search "ytsearch" (or run  youtube-dl "ytsearch:" ) to search YouTube

During handling of the above exception, another exception occurred:

Traceback (most recent call last):
  File "/home/pi/.local/lib/python3.9/site-packages/discord/client.py", line 343, in _run_event
    await coro(*args, **kwargs)
  File "/home/pi/bots/discord_bot/cogs/activities.py", line 80, in on_voice_state_update
    info = ydl.extract_info(url, download=False)
  File "/home/pi/.local/lib/python3.9/site-packages/youtube_dl/YoutubeDL.py", line 808, in extract_info
    return self.__extract_info(url, ie, download, extra_info, process)
  File "/home/pi/.local/lib/python3.9/site-packages/youtube_dl/YoutubeDL.py", line 824, in wrapper
    self.report_error(compat_str(e), e.format_traceback())
  File "/home/pi/.local/lib/python3.9/site-packages/youtube_dl/YoutubeDL.py", line 628, in report_error
    self.trouble(error_message, tb)
  File "/home/pi/.local/lib/python3.9/site-packages/youtube_dl/YoutubeDL.py", line 598, in trouble
    raise DownloadError(message, exc_info)
youtube_dl.utils.DownloadError: ERROR: '' is not a valid URL. Set --default-search "ytsearch" (or run  youtube-dl "ytsearch:" ) to search YouTube
ERROR: '' is not a valid URL. Set --default-search "ytsearch" (or run  youtube-dl "ytsearch:" ) to search YouTube
Ignoring exception in on_voice_state_update
Traceback (most recent call last):
  File "/home/pi/.local/lib/python3.9/site-packages/youtube_dl/YoutubeDL.py", line 815, in wrapper
    return func(self, *args, **kwargs)
  File "/home/pi/.local/lib/python3.9/site-packages/youtube_dl/YoutubeDL.py", line 836, in __extract_info
    ie_result = ie.extract(url)
  File "/home/pi/.local/lib/python3.9/site-packages/youtube_dl/extractor/common.py", line 534, in extract
    ie_result = self._real_extract(url)
  File "/home/pi/.local/lib/python3.9/site-packages/youtube_dl/extractor/generic.py", line 2361, in _real_extract
    raise ExtractorError(
youtube_dl.utils.ExtractorError: '' is not a valid URL. Set --default-search "ytsearch" (or run  youtube-dl "ytsearch:" ) to search YouTube

During handling of the above exception, another exception occurred:

Traceback (most recent call last):
  File "/home/pi/.local/lib/python3.9/site-packages/discord/client.py", line 343, in _run_event
    await coro(*args, **kwargs)
  File "/home/pi/bots/discord_bot/cogs/activities.py", line 80, in on_voice_state_update
    info = ydl.extract_info(url, download=False)
  File "/home/pi/.local/lib/python3.9/site-packages/youtube_dl/YoutubeDL.py", line 808, in extract_info
    return self.__extract_info(url, ie, download, extra_info, process)
  File "/home/pi/.local/lib/python3.9/site-packages/youtube_dl/YoutubeDL.py", line 824, in wrapper
    self.report_error(compat_str(e), e.format_traceback())
  File "/home/pi/.local/lib/python3.9/site-packages/youtube_dl/YoutubeDL.py", line 628, in report_error
    self.trouble(error_message, tb)
  File "/home/pi/.local/lib/python3.9/site-packages/youtube_dl/YoutubeDL.py", line 598, in trouble
    raise DownloadError(message, exc_info)
youtube_dl.utils.DownloadError: ERROR: '' is not a valid URL. Set --default-search "ytsearch" (or run  youtube-dl "ytsearch:" ) to search YouTube
Ignoring exception in on_voice_state_update
Traceback (most recent call last):
  File "/home/pi/.local/lib/python3.9/site-packages/discord/client.py", line 343, in _run_event
    await coro(*args, **kwargs)
  File "/home/pi/bots/discord_bot/cogs/activities.py", line 22, in on_voice_state_update
    voice_channel = member.voice.channel
AttributeError: 'NoneType' object has no attribute 'channel'
ERROR: '' is not a valid URL. Set --default-search "ytsearch" (or run  youtube-dl "ytsearch:" ) to search YouTube
Ignoring exception in on_voice_state_update
Traceback (most recent call last):
  File "/home/pi/.local/lib/python3.9/site-packages/youtube_dl/YoutubeDL.py", line 815, in wrapper
    return func(self, *args, **kwargs)
  File "/home/pi/.local/lib/python3.9/site-packages/youtube_dl/YoutubeDL.py", line 836, in __extract_info
    ie_result = ie.extract(url)
  File "/home/pi/.local/lib/python3.9/site-packages/youtube_dl/extractor/common.py", line 534, in extract
    ie_result = self._real_extract(url)
  File "/home/pi/.local/lib/python3.9/site-packages/youtube_dl/extractor/generic.py", line 2361, in _real_extract
    raise ExtractorError(
youtube_dl.utils.ExtractorError: '' is not a valid URL. Set --default-search "ytsearch" (or run  youtube-dl "ytsearch:" ) to search YouTube

During handling of the above exception, another exception occurred:

Traceback (most recent call last):
  File "/home/pi/.local/lib/python3.9/site-packages/discord/client.py", line 343, in _run_event
    await coro(*args, **kwargs)
  File "/home/pi/bots/discord_bot/cogs/activities.py", line 80, in on_voice_state_update
    info = ydl.extract_info(url, download=False)
  File "/home/pi/.local/lib/python3.9/site-packages/youtube_dl/YoutubeDL.py", line 808, in extract_info
    return self.__extract_info(url, ie, download, extra_info, process)
  File "/home/pi/.local/lib/python3.9/site-packages/youtube_dl/YoutubeDL.py", line 824, in wrapper
    self.report_error(compat_str(e), e.format_traceback())
  File "/home/pi/.local/lib/python3.9/site-packages/youtube_dl/YoutubeDL.py", line 628, in report_error
    self.trouble(error_message, tb)
  File "/home/pi/.local/lib/python3.9/site-packages/youtube_dl/YoutubeDL.py", line 598, in trouble
    raise DownloadError(message, exc_info)
youtube_dl.utils.DownloadError: ERROR: '' is not a valid URL. Set --default-search "ytsearch" (or run  youtube-dl "ytsearch:" ) to search YouTube
ERROR: '' is not a valid URL. Set --default-search "ytsearch" (or run  youtube-dl "ytsearch:" ) to search YouTube
Ignoring exception in on_voice_state_update
Traceback (most recent call last):
  File "/home/pi/.local/lib/python3.9/site-packages/youtube_dl/YoutubeDL.py", line 815, in wrapper
    return func(self, *args, **kwargs)
  File "/home/pi/.local/lib/python3.9/site-packages/youtube_dl/YoutubeDL.py", line 836, in __extract_info
    ie_result = ie.extract(url)
  File "/home/pi/.local/lib/python3.9/site-packages/youtube_dl/extractor/common.py", line 534, in extract
    ie_result = self._real_extract(url)
  File "/home/pi/.local/lib/python3.9/site-packages/youtube_dl/extractor/generic.py", line 2361, in _real_extract
    raise ExtractorError(
youtube_dl.utils.ExtractorError: '' is not a valid URL. Set --default-search "ytsearch" (or run  youtube-dl "ytsearch:" ) to search YouTube

During handling of the above exception, another exception occurred:

Traceback (most recent call last):
  File "/home/pi/.local/lib/python3.9/site-packages/discord/client.py", line 343, in _run_event
    await coro(*args, **kwargs)
  File "/home/pi/bots/discord_bot/cogs/activities.py", line 80, in on_voice_state_update
    info = ydl.extract_info(url, download=False)
  File "/home/pi/.local/lib/python3.9/site-packages/youtube_dl/YoutubeDL.py", line 808, in extract_info
    return self.__extract_info(url, ie, download, extra_info, process)
  File "/home/pi/.local/lib/python3.9/site-packages/youtube_dl/YoutubeDL.py", line 824, in wrapper
    self.report_error(compat_str(e), e.format_traceback())
  File "/home/pi/.local/lib/python3.9/site-packages/youtube_dl/YoutubeDL.py", line 628, in report_error
    self.trouble(error_message, tb)
  File "/home/pi/.local/lib/python3.9/site-packages/youtube_dl/YoutubeDL.py", line 598, in trouble
    raise DownloadError(message, exc_info)
youtube_dl.utils.DownloadError: ERROR: '' is not a valid URL. Set --default-search "ytsearch" (or run  youtube-dl "ytsearch:" ) to search YouTube
ERROR: '' is not a valid URL. Set --default-search "ytsearch" (or run  youtube-dl "ytsearch:" ) to search YouTube
Ignoring exception in on_voice_state_update
Traceback (most recent call last):
  File "/home/pi/.local/lib/python3.9/site-packages/youtube_dl/YoutubeDL.py", line 815, in wrapper
    return func(self, *args, **kwargs)
  File "/home/pi/.local/lib/python3.9/site-packages/youtube_dl/YoutubeDL.py", line 836, in __extract_info
    ie_result = ie.extract(url)
  File "/home/pi/.local/lib/python3.9/site-packages/youtube_dl/extractor/common.py", line 534, in extract
    ie_result = self._real_extract(url)
  File "/home/pi/.local/lib/python3.9/site-packages/youtube_dl/extractor/generic.py", line 2361, in _real_extract
    raise ExtractorError(
youtube_dl.utils.ExtractorError: '' is not a valid URL. Set --default-search "ytsearch" (or run  youtube-dl "ytsearch:" ) to search YouTube

During handling of the above exception, another exception occurred:

Traceback (most recent call last):
  File "/home/pi/.local/lib/python3.9/site-packages/discord/client.py", line 343, in _run_event
    await coro(*args, **kwargs)
  File "/home/pi/bots/discord_bot/cogs/activities.py", line 80, in on_voice_state_update
    info = ydl.extract_info(url, download=False)
  File "/home/pi/.local/lib/python3.9/site-packages/youtube_dl/YoutubeDL.py", line 808, in extract_info
    return self.__extract_info(url, ie, download, extra_info, process)
  File "/home/pi/.local/lib/python3.9/site-packages/youtube_dl/YoutubeDL.py", line 824, in wrapper
    self.report_error(compat_str(e), e.format_traceback())
  File "/home/pi/.local/lib/python3.9/site-packages/youtube_dl/YoutubeDL.py", line 628, in report_error
    self.trouble(error_message, tb)
  File "/home/pi/.local/lib/python3.9/site-packages/youtube_dl/YoutubeDL.py", line 598, in trouble
    raise DownloadError(message, exc_info)
youtube_dl.utils.DownloadError: ERROR: '' is not a valid URL. Set --default-search "ytsearch" (or run  youtube-dl "ytsearch:" ) to search YouTube
ERROR: '' is not a valid URL. Set --default-search "ytsearch" (or run  youtube-dl "ytsearch:" ) to search YouTube
Ignoring exception in on_voice_state_update
Traceback (most recent call last):
  File "/home/pi/.local/lib/python3.9/site-packages/youtube_dl/YoutubeDL.py", line 815, in wrapper
    return func(self, *args, **kwargs)
  File "/home/pi/.local/lib/python3.9/site-packages/youtube_dl/YoutubeDL.py", line 836, in __extract_info
    ie_result = ie.extract(url)
  File "/home/pi/.local/lib/python3.9/site-packages/youtube_dl/extractor/common.py", line 534, in extract
    ie_result = self._real_extract(url)
  File "/home/pi/.local/lib/python3.9/site-packages/youtube_dl/extractor/generic.py", line 2361, in _real_extract
    raise ExtractorError(
youtube_dl.utils.ExtractorError: '' is not a valid URL. Set --default-search "ytsearch" (or run  youtube-dl "ytsearch:" ) to search YouTube

During handling of the above exception, another exception occurred:

Traceback (most recent call last):
  File "/home/pi/.local/lib/python3.9/site-packages/discord/client.py", line 343, in _run_event
    await coro(*args, **kwargs)
  File "/home/pi/bots/discord_bot/cogs/activities.py", line 80, in on_voice_state_update
    info = ydl.extract_info(url, download=False)
  File "/home/pi/.local/lib/python3.9/site-packages/youtube_dl/YoutubeDL.py", line 808, in extract_info
    return self.__extract_info(url, ie, download, extra_info, process)
  File "/home/pi/.local/lib/python3.9/site-packages/youtube_dl/YoutubeDL.py", line 824, in wrapper
    self.report_error(compat_str(e), e.format_traceback())
  File "/home/pi/.local/lib/python3.9/site-packages/youtube_dl/YoutubeDL.py", line 628, in report_error
    self.trouble(error_message, tb)
  File "/home/pi/.local/lib/python3.9/site-packages/youtube_dl/YoutubeDL.py", line 598, in trouble
    raise DownloadError(message, exc_info)
youtube_dl.utils.DownloadError: ERROR: '' is not a valid URL. Set --default-search "ytsearch" (or run  youtube-dl "ytsearch:" ) to search YouTube
ERROR: '' is not a valid URL. Set --default-search "ytsearch" (or run  youtube-dl "ytsearch:" ) to search YouTube
Ignoring exception in on_voice_state_update
Traceback (most recent call last):
  File "/home/pi/.local/lib/python3.9/site-packages/youtube_dl/YoutubeDL.py", line 815, in wrapper
    return func(self, *args, **kwargs)
  File "/home/pi/.local/lib/python3.9/site-packages/youtube_dl/YoutubeDL.py", line 836, in __extract_info
    ie_result = ie.extract(url)
  File "/home/pi/.local/lib/python3.9/site-packages/youtube_dl/extractor/common.py", line 534, in extract
    ie_result = self._real_extract(url)
  File "/home/pi/.local/lib/python3.9/site-packages/youtube_dl/extractor/generic.py", line 2361, in _real_extract
    raise ExtractorError(
youtube_dl.utils.ExtractorError: '' is not a valid URL. Set --default-search "ytsearch" (or run  youtube-dl "ytsearch:" ) to search YouTube

During handling of the above exception, another exception occurred:

Traceback (most recent call last):
  File "/home/pi/.local/lib/python3.9/site-packages/discord/client.py", line 343, in _run_event
    await coro(*args, **kwargs)
  File "/home/pi/bots/discord_bot/cogs/activities.py", line 80, in on_voice_state_update
    info = ydl.extract_info(url, download=False)
  File "/home/pi/.local/lib/python3.9/site-packages/youtube_dl/YoutubeDL.py", line 808, in extract_info
    return self.__extract_info(url, ie, download, extra_info, process)
  File "/home/pi/.local/lib/python3.9/site-packages/youtube_dl/YoutubeDL.py", line 824, in wrapper
    self.report_error(compat_str(e), e.format_traceback())
  File "/home/pi/.local/lib/python3.9/site-packages/youtube_dl/YoutubeDL.py", line 628, in report_error
    self.trouble(error_message, tb)
  File "/home/pi/.local/lib/python3.9/site-packages/youtube_dl/YoutubeDL.py", line 598, in trouble
    raise DownloadError(message, exc_info)
youtube_dl.utils.DownloadError: ERROR: '' is not a valid URL. Set --default-search "ytsearch" (or run  youtube-dl "ytsearch:" ) to search YouTube
ERROR: '' is not a valid URL. Set --default-search "ytsearch" (or run  youtube-dl "ytsearch:" ) to search YouTube
Ignoring exception in on_voice_state_update
Traceback (most recent call last):
  File "/home/pi/.local/lib/python3.9/site-packages/youtube_dl/YoutubeDL.py", line 815, in wrapper
    return func(self, *args, **kwargs)
  File "/home/pi/.local/lib/python3.9/site-packages/youtube_dl/YoutubeDL.py", line 836, in __extract_info
    ie_result = ie.extract(url)
  File "/home/pi/.local/lib/python3.9/site-packages/youtube_dl/extractor/common.py", line 534, in extract
    ie_result = self._real_extract(url)
  File "/home/pi/.local/lib/python3.9/site-packages/youtube_dl/extractor/generic.py", line 2361, in _real_extract
    raise ExtractorError(
youtube_dl.utils.ExtractorError: '' is not a valid URL. Set --default-search "ytsearch" (or run  youtube-dl "ytsearch:" ) to search YouTube

During handling of the above exception, another exception occurred:

Traceback (most recent call last):
  File "/home/pi/.local/lib/python3.9/site-packages/discord/client.py", line 343, in _run_event
    await coro(*args, **kwargs)
  File "/home/pi/bots/discord_bot/cogs/activities.py", line 80, in on_voice_state_update
    info = ydl.extract_info(url, download=False)
  File "/home/pi/.local/lib/python3.9/site-packages/youtube_dl/YoutubeDL.py", line 808, in extract_info
    return self.__extract_info(url, ie, download, extra_info, process)
  File "/home/pi/.local/lib/python3.9/site-packages/youtube_dl/YoutubeDL.py", line 824, in wrapper
    self.report_error(compat_str(e), e.format_traceback())
  File "/home/pi/.local/lib/python3.9/site-packages/youtube_dl/YoutubeDL.py", line 628, in report_error
    self.trouble(error_message, tb)
  File "/home/pi/.local/lib/python3.9/site-packages/youtube_dl/YoutubeDL.py", line 598, in trouble
    raise DownloadError(message, exc_info)
youtube_dl.utils.DownloadError: ERROR: '' is not a valid URL. Set --default-search "ytsearch" (or run  youtube-dl "ytsearch:" ) to search YouTube
ERROR: '' is not a valid URL. Set --default-search "ytsearch" (or run  youtube-dl "ytsearch:" ) to search YouTube
Ignoring exception in on_voice_state_update
Traceback (most recent call last):
  File "/home/pi/.local/lib/python3.9/site-packages/youtube_dl/YoutubeDL.py", line 815, in wrapper
    return func(self, *args, **kwargs)
  File "/home/pi/.local/lib/python3.9/site-packages/youtube_dl/YoutubeDL.py", line 836, in __extract_info
    ie_result = ie.extract(url)
  File "/home/pi/.local/lib/python3.9/site-packages/youtube_dl/extractor/common.py", line 534, in extract
    ie_result = self._real_extract(url)
  File "/home/pi/.local/lib/python3.9/site-packages/youtube_dl/extractor/generic.py", line 2361, in _real_extract
    raise ExtractorError(
youtube_dl.utils.ExtractorError: '' is not a valid URL. Set --default-search "ytsearch" (or run  youtube-dl "ytsearch:" ) to search YouTube

During handling of the above exception, another exception occurred:

Traceback (most recent call last):
  File "/home/pi/.local/lib/python3.9/site-packages/discord/client.py", line 343, in _run_event
    await coro(*args, **kwargs)
  File "/home/pi/bots/discord_bot/cogs/activities.py", line 80, in on_voice_state_update
    info = ydl.extract_info(url, download=False)
  File "/home/pi/.local/lib/python3.9/site-packages/youtube_dl/YoutubeDL.py", line 808, in extract_info
    return self.__extract_info(url, ie, download, extra_info, process)
  File "/home/pi/.local/lib/python3.9/site-packages/youtube_dl/YoutubeDL.py", line 824, in wrapper
    self.report_error(compat_str(e), e.format_traceback())
  File "/home/pi/.local/lib/python3.9/site-packages/youtube_dl/YoutubeDL.py", line 628, in report_error
    self.trouble(error_message, tb)
  File "/home/pi/.local/lib/python3.9/site-packages/youtube_dl/YoutubeDL.py", line 598, in trouble
    raise DownloadError(message, exc_info)
youtube_dl.utils.DownloadError: ERROR: '' is not a valid URL. Set --default-search "ytsearch" (or run  youtube-dl "ytsearch:" ) to search YouTube
Bot StepBot joined Pernis
Bot StepBot joined Pernis
Bot StepBot joined Pernis
Bot StepBot joined Pernis
Bot StepBot joined Pernis
av_interleaved_write_frame(): Broken pipe
Error writing trailer of pipe:1: Broken pipe
Ignoring exception in on_voice_state_update
Traceback (most recent call last):
  File "/home/pi/.local/lib/python3.9/site-packages/discord/client.py", line 343, in _run_event
    await coro(*args, **kwargs)
  File "/home/pi/bots/discord_bot/cogs/activities.py", line 23, in on_voice_state_update
    voice_channel = member.voice.channel
AttributeError: 'NoneType' object has no attribute 'channel'
ERROR: '' is not a valid URL. Set --default-search "ytsearch" (or run  youtube-dl "ytsearch:" ) to search YouTube
Ignoring exception in on_voice_state_update
Traceback (most recent call last):
  File "/home/pi/.local/lib/python3.9/site-packages/youtube_dl/YoutubeDL.py", line 815, in wrapper
    return func(self, *args, **kwargs)
  File "/home/pi/.local/lib/python3.9/site-packages/youtube_dl/YoutubeDL.py", line 836, in __extract_info
    ie_result = ie.extract(url)
  File "/home/pi/.local/lib/python3.9/site-packages/youtube_dl/extractor/common.py", line 534, in extract
    ie_result = self._real_extract(url)
  File "/home/pi/.local/lib/python3.9/site-packages/youtube_dl/extractor/generic.py", line 2361, in _real_extract
    raise ExtractorError(
youtube_dl.utils.ExtractorError: '' is not a valid URL. Set --default-search "ytsearch" (or run  youtube-dl "ytsearch:" ) to search YouTube

During handling of the above exception, another exception occurred:

Traceback (most recent call last):
  File "/home/pi/.local/lib/python3.9/site-packages/discord/client.py", line 343, in _run_event
    await coro(*args, **kwargs)
  File "/home/pi/bots/discord_bot/cogs/activities.py", line 88, in on_voice_state_update
    info = ydl.extract_info(url, download=False)
  File "/home/pi/.local/lib/python3.9/site-packages/youtube_dl/YoutubeDL.py", line 808, in extract_info
    return self.__extract_info(url, ie, download, extra_info, process)
  File "/home/pi/.local/lib/python3.9/site-packages/youtube_dl/YoutubeDL.py", line 824, in wrapper
    self.report_error(compat_str(e), e.format_traceback())
  File "/home/pi/.local/lib/python3.9/site-packages/youtube_dl/YoutubeDL.py", line 628, in report_error
    self.trouble(error_message, tb)
  File "/home/pi/.local/lib/python3.9/site-packages/youtube_dl/YoutubeDL.py", line 598, in trouble
    raise DownloadError(message, exc_info)
youtube_dl.utils.DownloadError: ERROR: '' is not a valid URL. Set --default-search "ytsearch" (or run  youtube-dl "ytsearch:" ) to search YouTube
[youtube] 9_o4_4fwbpU: Downloading webpage
---------
 Chu pra
---------
somethin else happened
FrozenCheerios started streaming
13quik joined Pernis
Bot StepBot joined Pernis
[youtube] 9_o4_4fwbpU: Downloading MPD manifest
Ignoring exception in on_voice_state_update
Traceback (most recent call last):
  File "/home/pi/.local/lib/python3.9/site-packages/discord/client.py", line 343, in _run_event
    await coro(*args, **kwargs)
  File "/home/pi/bots/discord_bot/cogs/activities.py", line 23, in on_voice_state_update
    voice_channel = member.voice.channel
AttributeError: 'NoneType' object has no attribute 'channel'
Ignoring exception in on_voice_state_update
Traceback (most recent call last):
  File "/home/pi/.local/lib/python3.9/site-packages/discord/client.py", line 343, in _run_event
    await coro(*args, **kwargs)
  File "/home/pi/bots/discord_bot/cogs/activities.py", line 23, in on_voice_state_update
    voice_channel = member.voice.channel
AttributeError: 'NoneType' object has no attribute 'channel'
[youtube] 9_o4_4fwbpU: Downloading webpage
13quik joined Pernis
[youtube] 9_o4_4fwbpU: Downloading MPD manifest
[youtube] 6fILxnBH1Tg: Downloading webpage
FrozenCheerios joined Pernis
Ignoring exception in on_voice_state_update
Traceback (most recent call last):
  File "/home/pi/.local/lib/python3.9/site-packages/discord/client.py", line 343, in _run_event
    await coro(*args, **kwargs)
  File "/home/pi/bots/discord_bot/cogs/activities.py", line 92, in on_voice_state_update
    vc.play(source)
  File "/home/pi/.local/lib/python3.9/site-packages/discord/voice_client.py", line 558, in play
    raise ClientException('Already playing audio.')
discord.errors.ClientException: Already playing audio.
Ignoring exception in on_voice_state_update
Traceback (most recent call last):
  File "/home/pi/.local/lib/python3.9/site-packages/discord/client.py", line 343, in _run_event
    await coro(*args, **kwargs)
  File "/home/pi/bots/discord_bot/cogs/activities.py", line 23, in on_voice_state_update
    voice_channel = member.voice.channel
AttributeError: 'NoneType' object has no attribute 'channel'
[youtube] 9_o4_4fwbpU: Downloading webpage
13quik joined Pernis
[youtube] 9_o4_4fwbpU: Downloading MPD manifest
[youtube] _p2ymy8481Q: Downloading webpage
somethin else happened
[youtube] _p2ymy8481Q: Downloading webpage
somethin else happened
[youtube] _p2ymy8481Q: Downloading webpage
somethin else happened
[youtube] _p2ymy8481Q: Downloading webpage
somethin else happened
[https @ 0x55aa6c6ca0] HTTP error 403 Forbidden
https://rr3---sn-cxaaj5o5q5-t9cl.googlevideo.com/videoplayback?expire=1659222379&ei=CmXlYsCsPLmC2LYPg90L&ip=70.51.188.228&id=o-ALBt0fTDy47o1dPG_4JVLel90qz5-vCxvVpi9nGbo8_-&itag=249&source=youtube&requiressl=yes&mh=wh&mm=31%2C29&mn=sn-cxaaj5o5q5-t9cl%2Csn-cxaaj5o5q5-t0ar&ms=au%2Crdu&mv=m&mvi=3&pcm2cms=yes&pl=24&initcwndbps=2017500&spc=lT-KhoyO52XZLZ_jFSoZGpehn9C9hqc&vprv=1&mime=audio%2Fwebm&ns=rJUHfr6OsfLTaHHbKoRS3OMH&gir=yes&clen=2137558&dur=340.761&lmt=1548485019909307&mt=1659200457&fvip=1&keepalive=yes&fexp=24001373%2C24007246&c=WEB&rbqsm=fr&txp=5411222&n=9VRumc-z1I33ZX9r&sparams=expire%2Cei%2Cip%2Cid%2Citag%2Csource%2Crequiressl%2Cspc%2Cvprv%2Cmime%2Cns%2Cgir%2Cclen%2Cdur%2Clmt&lsparams=mh%2Cmm%2Cmn%2Cms%2Cmv%2Cmvi%2Cpcm2cms%2Cpl%2Cinitcwndbps&lsig=AG3C_xAwRAIgJ-0fJGTW8svQ2I1HDA8nLbeyN70vElQffO2VUaPxEwYCIAqR9sEGxTE_4-s-DxM3Nl14e9w9Vq2mrPWvfQ5YcruO&sig=AOq0QJ8wRQIgH7np2_V6AodSPMLyZOuP6WVAl9AXP1sxYPf96O0SUc0CIQC17lRnfFCS6PgHfVbq3VZJ5hNsTMAlPsxgv6AdtbFW0Q==: Server returned 403 Forbidden (access denied)
[youtube] _p2ymy8481Q: Downloading webpage
somethin else happened
[youtube] 9_o4_4fwbpU: Downloading webpage
somethin else happened
[youtube] 9_o4_4fwbpU: Downloading MPD manifest
[youtube] 9_o4_4fwbpU: Downloading webpage
somethin else happened
[youtube] 9_o4_4fwbpU: Downloading MPD manifest
[youtube] 9_o4_4fwbpU: Downloading webpage
somethin else happened
[youtube] 9_o4_4fwbpU: Downloading MPD manifest
[youtube] 9_o4_4fwbpU: Downloading webpage
somethin else happened
[youtube] 9_o4_4fwbpU: Downloading MPD manifest
Ignoring exception in on_voice_state_update
Traceback (most recent call last):
  File "/home/pi/.local/lib/python3.9/site-packages/discord/client.py", line 343, in _run_event
    await coro(*args, **kwargs)
  File "/home/pi/bots/discord_bot/cogs/activities.py", line 92, in on_voice_state_update
    vc.play(source)
  File "/home/pi/.local/lib/python3.9/site-packages/discord/voice_client.py", line 558, in play
    raise ClientException('Already playing audio.')
discord.errors.ClientException: Already playing audio.
Ignoring exception in on_voice_state_update
Traceback (most recent call last):
  File "/home/pi/.local/lib/python3.9/site-packages/discord/client.py", line 343, in _run_event
    await coro(*args, **kwargs)
  File "/home/pi/bots/discord_bot/cogs/activities.py", line 92, in on_voice_state_update
    vc.play(source)
  File "/home/pi/.local/lib/python3.9/site-packages/discord/voice_client.py", line 558, in play
    raise ClientException('Already playing audio.')
discord.errors.ClientException: Already playing audio.
[youtube] _p2ymy8481Q: Downloading webpage
somethin else happened
[youtube] _p2ymy8481Q: Downloading webpage
somethin else happened
[youtube] _p2ymy8481Q: Downloading webpage
somethin else happened
[youtube] _p2ymy8481Q: Downloading webpage
somethin else happened
[youtube] _p2ymy8481Q: Downloading webpage
somethin else happened
Ignoring exception in on_voice_state_update
Traceback (most recent call last):
  File "/home/pi/.local/lib/python3.9/site-packages/discord/client.py", line 343, in _run_event
    await coro(*args, **kwargs)
  File "/home/pi/bots/discord_bot/cogs/activities.py", line 92, in on_voice_state_update
    vc.play(source)
  File "/home/pi/.local/lib/python3.9/site-packages/discord/voice_client.py", line 558, in play
    raise ClientException('Already playing audio.')
discord.errors.ClientException: Already playing audio.
Ignoring exception in on_voice_state_update
Traceback (most recent call last):
  File "/home/pi/.local/lib/python3.9/site-packages/discord/client.py", line 343, in _run_event
    await coro(*args, **kwargs)
  File "/home/pi/bots/discord_bot/cogs/activities.py", line 23, in on_voice_state_update
    voice_channel = member.voice.channel
AttributeError: 'NoneType' object has no attribute 'channel'
[youtube] 6fILxnBH1Tg: Downloading webpage
somethin else happened
13quik started streaming
FrozenCheerios joined Pernis
[youtube] _p2ymy8481Q: Downloading webpage
somethin else happened
[youtube] 9_o4_4fwbpU: Downloading webpage
somethin else happened
[youtube] 9_o4_4fwbpU: Downloading MPD manifest
somethin else happened
FrozenCheerios started streaming
Ignoring exception in on_voice_state_update
Traceback (most recent call last):
  File "/home/pi/.local/lib/python3.9/site-packages/discord/client.py", line 343, in _run_event
    await coro(*args, **kwargs)
  File "/home/pi/bots/discord_bot/cogs/activities.py", line 84, in on_voice_state_update
    player = vc.FFmpegOpusAudio(url, after=lambda: print('done'))
AttributeError: 'VoiceClient' object has no attribute 'FFmpegOpusAudio'
[youtube] -GyzXuK-gtI: Downloading webpage
---------
 Chu pra
---------
Bot StepBot joined Pernis
Ignoring exception in command play:
Traceback (most recent call last):
  File "/home/pi/.local/lib/python3.9/site-packages/discord/ext/commands/core.py", line 85, in wrapped
    ret = await coro(*args, **kwargs)
  File "/home/pi/bots/discord_bot/cogs/music.py", line 52, in play
    await vc.play(source)
TypeError: object NoneType can't be used in 'await' expression

The above exception was the direct cause of the following exception:

Traceback (most recent call last):
  File "/home/pi/.local/lib/python3.9/site-packages/discord/ext/commands/bot.py", line 939, in invoke
    await ctx.command.invoke(ctx)
  File "/home/pi/.local/lib/python3.9/site-packages/discord/ext/commands/core.py", line 863, in invoke
    await injected(*ctx.args, **ctx.kwargs)
  File "/home/pi/.local/lib/python3.9/site-packages/discord/ext/commands/core.py", line 94, in wrapped
    raise CommandInvokeError(exc) from exc
discord.ext.commands.errors.CommandInvokeError: Command raised an exception: TypeError: object NoneType can't be used in 'await' expression
Ignoring exception in on_voice_state_update
Traceback (most recent call last):
  File "/home/pi/.local/lib/python3.9/site-packages/discord/client.py", line 343, in _run_event
    await coro(*args, **kwargs)
  File "/home/pi/bots/discord_bot/cogs/activities.py", line 84, in on_voice_state_update
    player = vc.FFmpegOpusAudio(url, after=lambda: print('done'))
AttributeError: 'VoiceClient' object has no attribute 'FFmpegOpusAudio'
Ignoring exception in on_voice_state_update
Traceback (most recent call last):
  File "/home/pi/.local/lib/python3.9/site-packages/discord/client.py", line 343, in _run_event
    await coro(*args, **kwargs)
  File "/home/pi/bots/discord_bot/cogs/activities.py", line 23, in on_voice_state_update
    voice_channel = member.voice.channel
AttributeError: 'NoneType' object has no attribute 'channel'
Ignoring exception in on_voice_state_update
Traceback (most recent call last):
  File "/home/pi/.local/lib/python3.9/site-packages/discord/client.py", line 343, in _run_event
    await coro(*args, **kwargs)
  File "/home/pi/bots/discord_bot/cogs/activities.py", line 23, in on_voice_state_update
    voice_channel = member.voice.channel
AttributeError: 'NoneType' object has no attribute 'channel'
Ignoring exception in command None:
discord.ext.commands.errors.CommandNotFound: Command "p" is not found
Ignoring exception in on_voice_state_update
Traceback (most recent call last):
  File "/home/pi/.local/lib/python3.9/site-packages/discord/client.py", line 343, in _run_event
    await coro(*args, **kwargs)
  File "/home/pi/bots/discord_bot/cogs/activities.py", line 84, in on_voice_state_update
    player = vc.FFmpegOpusAudio(url, after=lambda: print('done'))
AttributeError: 'VoiceClient' object has no attribute 'FFmpegOpusAudio'
It appears that you are using PRAW in an asynchronous environment.
It is strongly recommended to use Async PRAW: https://asyncpraw.readthedocs.io.
See https://praw.readthedocs.io/en/latest/getting_started/multiple_instances.html#discord-bots-and-asynchronous-environments for more info.

Ignoring exception in on_voice_state_update
Traceback (most recent call last):
  File "/home/pi/.local/lib/python3.9/site-packages/discord/client.py", line 343, in _run_event
    await coro(*args, **kwargs)
  File "/home/pi/bots/discord_bot/cogs/activities.py", line 23, in on_voice_state_update
    voice_channel = member.voice.channel
AttributeError: 'NoneType' object has no attribute 'channel'
Ignoring exception in on_voice_state_update
Traceback (most recent call last):
  File "/home/pi/.local/lib/python3.9/site-packages/discord/client.py", line 343, in _run_event
    await coro(*args, **kwargs)
  File "/home/pi/bots/discord_bot/cogs/activities.py", line 23, in on_voice_state_update
    voice_channel = member.voice.channel
AttributeError: 'NoneType' object has no attribute 'channel'
Ignoring exception in on_voice_state_update
Traceback (most recent call last):
  File "/home/pi/.local/lib/python3.9/site-packages/discord/client.py", line 343, in _run_event
    await coro(*args, **kwargs)
  File "/home/pi/bots/discord_bot/cogs/activities.py", line 84, in on_voice_state_update
    player = vc.FFmpegOpusAudio(url, after=lambda: print('done'))
AttributeError: 'VoiceClient' object has no attribute 'FFmpegOpusAudio'
Ignoring exception in on_voice_state_update
Traceback (most recent call last):
  File "/home/pi/.local/lib/python3.9/site-packages/discord/client.py", line 343, in _run_event
    await coro(*args, **kwargs)
  File "/home/pi/bots/discord_bot/cogs/activities.py", line 23, in on_voice_state_update
    voice_channel = member.voice.channel
AttributeError: 'NoneType' object has no attribute 'channel'
Ignoring exception in on_voice_state_update
Traceback (most recent call last):
  File "/home/pi/.local/lib/python3.9/site-packages/discord/client.py", line 343, in _run_event
    await coro(*args, **kwargs)
  File "/home/pi/bots/discord_bot/cogs/activities.py", line 84, in on_voice_state_update
    player = vc.FFmpegOpusAudio(url, after=lambda: print('done'))
AttributeError: 'VoiceClient' object has no attribute 'FFmpegOpusAudio'
Ignoring exception in on_voice_state_update
Traceback (most recent call last):
  File "/home/pi/.local/lib/python3.9/site-packages/discord/client.py", line 343, in _run_event
    await coro(*args, **kwargs)
  File "/home/pi/bots/discord_bot/cogs/activities.py", line 23, in on_voice_state_update
    voice_channel = member.voice.channel
AttributeError: 'NoneType' object has no attribute 'channel'
Ignoring exception in on_voice_state_update
Traceback (most recent call last):
  File "/home/pi/.local/lib/python3.9/site-packages/discord/client.py", line 343, in _run_event
    await coro(*args, **kwargs)
  File "/home/pi/bots/discord_bot/cogs/activities.py", line 23, in on_voice_state_update
    voice_channel = member.voice.channel
AttributeError: 'NoneType' object has no attribute 'channel'
Ignoring exception in on_voice_state_update
Traceback (most recent call last):
  File "/home/pi/.local/lib/python3.9/site-packages/discord/client.py", line 343, in _run_event
    await coro(*args, **kwargs)
  File "/home/pi/bots/discord_bot/cogs/activities.py", line 84, in on_voice_state_update
    player = vc.FFmpegOpusAudio(url, after=lambda: print('done'))
AttributeError: 'VoiceClient' object has no attribute 'FFmpegOpusAudio'
Ignoring exception in on_voice_state_update
Traceback (most recent call last):
  File "/home/pi/.local/lib/python3.9/site-packages/discord/client.py", line 343, in _run_event
    await coro(*args, **kwargs)
  File "/home/pi/bots/discord_bot/cogs/activities.py", line 84, in on_voice_state_update
    player = vc.FFmpegOpusAudio(url, after=lambda: print('done'))
AttributeError: 'VoiceClient' object has no attribute 'FFmpegOpusAudio'
Ignoring exception in on_voice_state_update
Traceback (most recent call last):
  File "/home/pi/.local/lib/python3.9/site-packages/discord/client.py", line 343, in _run_event
    await coro(*args, **kwargs)
  File "/home/pi/bots/discord_bot/cogs/activities.py", line 84, in on_voice_state_update
    player = vc.FFmpegOpusAudio(url, after=lambda: print('done'))
AttributeError: 'VoiceClient' object has no attribute 'FFmpegOpusAudio'
Ignoring exception in on_voice_state_update
Traceback (most recent call last):
  File "/home/pi/.local/lib/python3.9/site-packages/discord/client.py", line 343, in _run_event
    await coro(*args, **kwargs)
  File "/home/pi/bots/discord_bot/cogs/activities.py", line 84, in on_voice_state_update
    player = vc.FFmpegOpusAudio(url, after=lambda: print('done'))
AttributeError: 'VoiceClient' object has no attribute 'FFmpegOpusAudio'
Ignoring exception in on_voice_state_update
Traceback (most recent call last):
  File "/home/pi/.local/lib/python3.9/site-packages/discord/client.py", line 343, in _run_event
    await coro(*args, **kwargs)
  File "/home/pi/bots/discord_bot/cogs/activities.py", line 84, in on_voice_state_update
    player = vc.FFmpegOpusAudio(url, after=lambda: print('done'))
AttributeError: 'VoiceClient' object has no attribute 'FFmpegOpusAudio'
Ignoring exception in on_voice_state_update
Traceback (most recent call last):
  File "/home/pi/.local/lib/python3.9/site-packages/discord/client.py", line 343, in _run_event
    await coro(*args, **kwargs)
  File "/home/pi/bots/discord_bot/cogs/activities.py", line 84, in on_voice_state_update
    player = vc.FFmpegOpusAudio(url, after=lambda: print('done'))
AttributeError: 'VoiceClient' object has no attribute 'FFmpegOpusAudio'
Ignoring exception in on_voice_state_update
Traceback (most recent call last):
  File "/home/pi/.local/lib/python3.9/site-packages/discord/client.py", line 343, in _run_event
    await coro(*args, **kwargs)
  File "/home/pi/bots/discord_bot/cogs/activities.py", line 84, in on_voice_state_update
    player = vc.FFmpegOpusAudio(url, after=lambda: print('done'))
AttributeError: 'VoiceClient' object has no attribute 'FFmpegOpusAudio'
Ignoring exception in on_voice_state_update
Traceback (most recent call last):
  File "/home/pi/.local/lib/python3.9/site-packages/discord/client.py", line 343, in _run_event
    await coro(*args, **kwargs)
  File "/home/pi/bots/discord_bot/cogs/activities.py", line 23, in on_voice_state_update
    voice_channel = member.voice.channel
AttributeError: 'NoneType' object has no attribute 'channel'
Ignoring exception in on_voice_state_update
Traceback (most recent call last):
  File "/home/pi/.local/lib/python3.9/site-packages/discord/client.py", line 343, in _run_event
    await coro(*args, **kwargs)
  File "/home/pi/bots/discord_bot/cogs/activities.py", line 23, in on_voice_state_update
    voice_channel = member.voice.channel
AttributeError: 'NoneType' object has no attribute 'channel'
Ignoring exception in on_voice_state_update
Traceback (most recent call last):
  File "/home/pi/.local/lib/python3.9/site-packages/discord/client.py", line 343, in _run_event
    await coro(*args, **kwargs)
  File "/home/pi/bots/discord_bot/cogs/activities.py", line 23, in on_voice_state_update
    voice_channel = member.voice.channel
AttributeError: 'NoneType' object has no attribute 'channel'
Ignoring exception in on_voice_state_update
Traceback (most recent call last):
  File "/home/pi/.local/lib/python3.9/site-packages/discord/client.py", line 343, in _run_event
    await coro(*args, **kwargs)
  File "/home/pi/bots/discord_bot/cogs/activities.py", line 84, in on_voice_state_update
    player = vc.FFmpegOpusAudio(url, after=lambda: print('done'))
AttributeError: 'VoiceClient' object has no attribute 'FFmpegOpusAudio'
Ignoring exception in on_voice_state_update
Traceback (most recent call last):
  File "/home/pi/.local/lib/python3.9/site-packages/discord/client.py", line 343, in _run_event
    await coro(*args, **kwargs)
  File "/home/pi/bots/discord_bot/cogs/activities.py", line 84, in on_voice_state_update
    player = vc.FFmpegOpusAudio(url, after=lambda: print('done'))
AttributeError: 'VoiceClient' object has no attribute 'FFmpegOpusAudio'
Ignoring exception in on_voice_state_update
Traceback (most recent call last):
  File "/home/pi/.local/lib/python3.9/site-packages/discord/client.py", line 343, in _run_event
    await coro(*args, **kwargs)
  File "/home/pi/bots/discord_bot/cogs/activities.py", line 84, in on_voice_state_update
    player = vc.FFmpegOpusAudio(url, after=lambda: print('done'))
AttributeError: 'VoiceClient' object has no attribute 'FFmpegOpusAudio'
Ignoring exception in on_voice_state_update
Traceback (most recent call last):
  File "/home/pi/.local/lib/python3.9/site-packages/discord/client.py", line 343, in _run_event
    await coro(*args, **kwargs)
  File "/home/pi/bots/discord_bot/cogs/activities.py", line 84, in on_voice_state_update
    player = vc.FFmpegOpusAudio(url, after=lambda: print('done'))
AttributeError: 'VoiceClient' object has no attribute 'FFmpegOpusAudio'
Ignoring exception in on_voice_state_update
Traceback (most recent call last):
  File "/home/pi/.local/lib/python3.9/site-packages/discord/client.py", line 343, in _run_event
    await coro(*args, **kwargs)
  File "/home/pi/bots/discord_bot/cogs/activities.py", line 84, in on_voice_state_update
    player = vc.FFmpegOpusAudio(url, after=lambda: print('done'))
AttributeError: 'VoiceClient' object has no attribute 'FFmpegOpusAudio'
Ignoring exception in on_voice_state_update
Traceback (most recent call last):
  File "/home/pi/.local/lib/python3.9/site-packages/discord/client.py", line 343, in _run_event
    await coro(*args, **kwargs)
  File "/home/pi/bots/discord_bot/cogs/activities.py", line 84, in on_voice_state_update
    player = vc.FFmpegOpusAudio(url, after=lambda: print('done'))
AttributeError: 'VoiceClient' object has no attribute 'FFmpegOpusAudio'
Ignoring exception in on_voice_state_update
Traceback (most recent call last):
  File "/home/pi/.local/lib/python3.9/site-packages/discord/client.py", line 343, in _run_event
    await coro(*args, **kwargs)
  File "/home/pi/bots/discord_bot/cogs/activities.py", line 84, in on_voice_state_update
    player = vc.FFmpegOpusAudio(url, after=lambda: print('done'))
AttributeError: 'VoiceClient' object has no attribute 'FFmpegOpusAudio'
Ignoring exception in on_voice_state_update
Traceback (most recent call last):
  File "/home/pi/.local/lib/python3.9/site-packages/discord/client.py", line 343, in _run_event
    await coro(*args, **kwargs)
  File "/home/pi/bots/discord_bot/cogs/activities.py", line 84, in on_voice_state_update
    player = vc.FFmpegOpusAudio(url, after=lambda: print('done'))
AttributeError: 'VoiceClient' object has no attribute 'FFmpegOpusAudio'
Ignoring exception in on_voice_state_update
Traceback (most recent call last):
  File "/home/pi/.local/lib/python3.9/site-packages/discord/client.py", line 343, in _run_event
    await coro(*args, **kwargs)
  File "/home/pi/bots/discord_bot/cogs/activities.py", line 84, in on_voice_state_update
    player = vc.FFmpegOpusAudio(url, after=lambda: print('done'))
AttributeError: 'VoiceClient' object has no attribute 'FFmpegOpusAudio'
Ignoring exception in on_voice_state_update
Traceback (most recent call last):
  File "/home/pi/.local/lib/python3.9/site-packages/discord/client.py", line 343, in _run_event
    await coro(*args, **kwargs)
  File "/home/pi/bots/discord_bot/cogs/activities.py", line 84, in on_voice_state_update
    player = vc.FFmpegOpusAudio(url, after=lambda: print('done'))
AttributeError: 'VoiceClient' object has no attribute 'FFmpegOpusAudio'
Ignoring exception in on_voice_state_update
Traceback (most recent call last):
  File "/home/pi/.local/lib/python3.9/site-packages/discord/client.py", line 343, in _run_event
    await coro(*args, **kwargs)
  File "/home/pi/bots/discord_bot/cogs/activities.py", line 84, in on_voice_state_update
    player = vc.FFmpegOpusAudio(url, after=lambda: print('done'))
AttributeError: 'VoiceClient' object has no attribute 'FFmpegOpusAudio'
Ignoring exception in on_voice_state_update
Traceback (most recent call last):
  File "/home/pi/.local/lib/python3.9/site-packages/discord/client.py", line 343, in _run_event
    await coro(*args, **kwargs)
  File "/home/pi/bots/discord_bot/cogs/activities.py", line 84, in on_voice_state_update
    player = vc.FFmpegOpusAudio(url, after=lambda: print('done'))
AttributeError: 'VoiceClient' object has no attribute 'FFmpegOpusAudio'
Ignoring exception in on_voice_state_update
Traceback (most recent call last):
  File "/home/pi/.local/lib/python3.9/site-packages/discord/client.py", line 343, in _run_event
    await coro(*args, **kwargs)
  File "/home/pi/bots/discord_bot/cogs/activities.py", line 84, in on_voice_state_update
    player = vc.FFmpegOpusAudio(url, after=lambda: print('done'))
AttributeError: 'VoiceClient' object has no attribute 'FFmpegOpusAudio'
Ignoring exception in on_voice_state_update
Traceback (most recent call last):
  File "/home/pi/.local/lib/python3.9/site-packages/discord/client.py", line 343, in _run_event
    await coro(*args, **kwargs)
  File "/home/pi/bots/discord_bot/cogs/activities.py", line 84, in on_voice_state_update
    player = vc.FFmpegOpusAudio(url, after=lambda: print('done'))
AttributeError: 'VoiceClient' object has no attribute 'FFmpegOpusAudio'
Ignoring exception in on_voice_state_update
Traceback (most recent call last):
  File "/home/pi/.local/lib/python3.9/site-packages/discord/client.py", line 343, in _run_event
    await coro(*args, **kwargs)
  File "/home/pi/bots/discord_bot/cogs/activities.py", line 84, in on_voice_state_update
    player = vc.FFmpegOpusAudio(url, after=lambda: print('done'))
AttributeError: 'VoiceClient' object has no attribute 'FFmpegOpusAudio'
Ignoring exception in on_voice_state_update
Traceback (most recent call last):
  File "/home/pi/.local/lib/python3.9/site-packages/discord/client.py", line 343, in _run_event
    await coro(*args, **kwargs)
  File "/home/pi/bots/discord_bot/cogs/activities.py", line 84, in on_voice_state_update
    player = vc.FFmpegOpusAudio(url, after=lambda: print('done'))
AttributeError: 'VoiceClient' object has no attribute 'FFmpegOpusAudio'
Ignoring exception in on_voice_state_update
Traceback (most recent call last):
  File "/home/pi/.local/lib/python3.9/site-packages/discord/client.py", line 343, in _run_event
    await coro(*args, **kwargs)
  File "/home/pi/bots/discord_bot/cogs/activities.py", line 84, in on_voice_state_update
    player = vc.FFmpegOpusAudio(url, after=lambda: print('done'))
AttributeError: 'VoiceClient' object has no attribute 'FFmpegOpusAudio'
Ignoring exception in on_voice_state_update
Traceback (most recent call last):
  File "/home/pi/.local/lib/python3.9/site-packages/discord/client.py", line 343, in _run_event
    await coro(*args, **kwargs)
  File "/home/pi/bots/discord_bot/cogs/activities.py", line 84, in on_voice_state_update
    player = vc.FFmpegOpusAudio(url, after=lambda: print('done'))
AttributeError: 'VoiceClient' object has no attribute 'FFmpegOpusAudio'
Ignoring exception in on_voice_state_update
Traceback (most recent call last):
  File "/home/pi/.local/lib/python3.9/site-packages/discord/client.py", line 343, in _run_event
    await coro(*args, **kwargs)
  File "/home/pi/bots/discord_bot/cogs/activities.py", line 23, in on_voice_state_update
    voice_channel = member.voice.channel
AttributeError: 'NoneType' object has no attribute 'channel'
Ignoring exception in on_voice_state_update
Traceback (most recent call last):
  File "/home/pi/.local/lib/python3.9/site-packages/discord/client.py", line 343, in _run_event
    await coro(*args, **kwargs)
  File "/home/pi/bots/discord_bot/cogs/activities.py", line 84, in on_voice_state_update
    player = vc.FFmpegOpusAudio(url, after=lambda: print('done'))
AttributeError: 'VoiceClient' object has no attribute 'FFmpegOpusAudio'
Ignoring exception in on_voice_state_update
Traceback (most recent call last):
  File "/home/pi/.local/lib/python3.9/site-packages/discord/client.py", line 343, in _run_event
    await coro(*args, **kwargs)
  File "/home/pi/bots/discord_bot/cogs/activities.py", line 84, in on_voice_state_update
    player = vc.FFmpegOpusAudio(url, after=lambda: print('done'))
AttributeError: 'VoiceClient' object has no attribute 'FFmpegOpusAudio'
Ignoring exception in on_voice_state_update
Traceback (most recent call last):
  File "/home/pi/.local/lib/python3.9/site-packages/discord/client.py", line 343, in _run_event
    await coro(*args, **kwargs)
  File "/home/pi/bots/discord_bot/cogs/activities.py", line 84, in on_voice_state_update
    player = vc.FFmpegOpusAudio(url, after=lambda: print('done'))
AttributeError: 'VoiceClient' object has no attribute 'FFmpegOpusAudio'
Ignoring exception in on_voice_state_update
Traceback (most recent call last):
  File "/home/pi/.local/lib/python3.9/site-packages/discord/client.py", line 343, in _run_event
    await coro(*args, **kwargs)
  File "/home/pi/bots/discord_bot/cogs/activities.py", line 84, in on_voice_state_update
    player = vc.FFmpegOpusAudio(url, after=lambda: print('done'))
AttributeError: 'VoiceClient' object has no attribute 'FFmpegOpusAudio'
Ignoring exception in on_voice_state_update
Traceback (most recent call last):
  File "/home/pi/.local/lib/python3.9/site-packages/discord/client.py", line 343, in _run_event
    await coro(*args, **kwargs)
  File "/home/pi/bots/discord_bot/cogs/activities.py", line 84, in on_voice_state_update
    player = vc.FFmpegOpusAudio(url, after=lambda: print('done'))
AttributeError: 'VoiceClient' object has no attribute 'FFmpegOpusAudio'
Ignoring exception in on_voice_state_update
Traceback (most recent call last):
  File "/home/pi/.local/lib/python3.9/site-packages/discord/client.py", line 343, in _run_event
    await coro(*args, **kwargs)
  File "/home/pi/bots/discord_bot/cogs/activities.py", line 84, in on_voice_state_update
    player = vc.FFmpegOpusAudio(url, after=lambda: print('done'))
AttributeError: 'VoiceClient' object has no attribute 'FFmpegOpusAudio'
Ignoring exception in on_voice_state_update
Traceback (most recent call last):
  File "/home/pi/.local/lib/python3.9/site-packages/discord/client.py", line 343, in _run_event
    await coro(*args, **kwargs)
  File "/home/pi/bots/discord_bot/cogs/activities.py", line 23, in on_voice_state_update
    voice_channel = member.voice.channel
AttributeError: 'NoneType' object has no attribute 'channel'
Ignoring exception in on_voice_state_update
Traceback (most recent call last):
  File "/home/pi/.local/lib/python3.9/site-packages/discord/client.py", line 343, in _run_event
    await coro(*args, **kwargs)
  File "/home/pi/bots/discord_bot/cogs/activities.py", line 23, in on_voice_state_update
    voice_channel = member.voice.channel
AttributeError: 'NoneType' object has no attribute 'channel'
Ignoring exception in on_voice_state_update
Traceback (most recent call last):
  File "/home/pi/.local/lib/python3.9/site-packages/discord/client.py", line 343, in _run_event
    await coro(*args, **kwargs)
  File "/home/pi/bots/discord_bot/cogs/activities.py", line 84, in on_voice_state_update
    player = vc.FFmpegOpusAudio(url, after=lambda: print('done'))
AttributeError: 'VoiceClient' object has no attribute 'FFmpegOpusAudio'
Ignoring exception in on_voice_state_update
Traceback (most recent call last):
  File "/home/pi/.local/lib/python3.9/site-packages/discord/client.py", line 343, in _run_event
    await coro(*args, **kwargs)
  File "/home/pi/bots/discord_bot/cogs/activities.py", line 84, in on_voice_state_update
    player = vc.FFmpegOpusAudio(url, after=lambda: print('done'))
AttributeError: 'VoiceClient' object has no attribute 'FFmpegOpusAudio'
Ignoring exception in on_voice_state_update
Traceback (most recent call last):
  File "/home/pi/.local/lib/python3.9/site-packages/discord/client.py", line 343, in _run_event
    await coro(*args, **kwargs)
  File "/home/pi/bots/discord_bot/cogs/activities.py", line 23, in on_voice_state_update
    voice_channel = member.voice.channel
AttributeError: 'NoneType' object has no attribute 'channel'
Ignoring exception in on_voice_state_update
Traceback (most recent call last):
  File "/home/pi/.local/lib/python3.9/site-packages/discord/client.py", line 343, in _run_event
    await coro(*args, **kwargs)
  File "/home/pi/bots/discord_bot/cogs/activities.py", line 84, in on_voice_state_update
    player = vc.FFmpegOpusAudio(url, after=lambda: print('done'))
AttributeError: 'VoiceClient' object has no attribute 'FFmpegOpusAudio'
Ignoring exception in on_voice_state_update
Traceback (most recent call last):
  File "/home/pi/.local/lib/python3.9/site-packages/discord/client.py", line 343, in _run_event
    await coro(*args, **kwargs)
  File "/home/pi/bots/discord_bot/cogs/activities.py", line 84, in on_voice_state_update
    player = vc.FFmpegOpusAudio(url, after=lambda: print('done'))
AttributeError: 'VoiceClient' object has no attribute 'FFmpegOpusAudio'
Ignoring exception in on_voice_state_update
Traceback (most recent call last):
  File "/home/pi/.local/lib/python3.9/site-packages/discord/client.py", line 343, in _run_event
    await coro(*args, **kwargs)
  File "/home/pi/bots/discord_bot/cogs/activities.py", line 84, in on_voice_state_update
    player = vc.FFmpegOpusAudio(url, after=lambda: print('done'))
AttributeError: 'VoiceClient' object has no attribute 'FFmpegOpusAudio'
Ignoring exception in on_voice_state_update
Traceback (most recent call last):
  File "/home/pi/.local/lib/python3.9/site-packages/discord/client.py", line 343, in _run_event
    await coro(*args, **kwargs)
  File "/home/pi/bots/discord_bot/cogs/activities.py", line 23, in on_voice_state_update
    voice_channel = member.voice.channel
AttributeError: 'NoneType' object has no attribute 'channel'
Ignoring exception in on_voice_state_update
Traceback (most recent call last):
  File "/home/pi/.local/lib/python3.9/site-packages/discord/client.py", line 343, in _run_event
    await coro(*args, **kwargs)
  File "/home/pi/bots/discord_bot/cogs/activities.py", line 84, in on_voice_state_update
    player = vc.FFmpegOpusAudio(url, after=lambda: print('done'))
AttributeError: 'VoiceClient' object has no attribute 'FFmpegOpusAudio'
Ignoring exception in on_voice_state_update
Traceback (most recent call last):
  File "/home/pi/.local/lib/python3.9/site-packages/discord/client.py", line 343, in _run_event
    await coro(*args, **kwargs)
  File "/home/pi/bots/discord_bot/cogs/activities.py", line 84, in on_voice_state_update
    player = vc.FFmpegOpusAudio(url, after=lambda: print('done'))
AttributeError: 'VoiceClient' object has no attribute 'FFmpegOpusAudio'
Ignoring exception in on_voice_state_update
Traceback (most recent call last):
  File "/home/pi/.local/lib/python3.9/site-packages/discord/client.py", line 343, in _run_event
    await coro(*args, **kwargs)
  File "/home/pi/bots/discord_bot/cogs/activities.py", line 84, in on_voice_state_update
    player = vc.FFmpegOpusAudio(url, after=lambda: print('done'))
AttributeError: 'VoiceClient' object has no attribute 'FFmpegOpusAudio'
Ignoring exception in on_voice_state_update
Traceback (most recent call last):
  File "/home/pi/.local/lib/python3.9/site-packages/discord/client.py", line 343, in _run_event
    await coro(*args, **kwargs)
  File "/home/pi/bots/discord_bot/cogs/activities.py", line 23, in on_voice_state_update
    voice_channel = member.voice.channel
AttributeError: 'NoneType' object has no attribute 'channel'
Ignoring exception in on_voice_state_update
Traceback (most recent call last):
  File "/home/pi/.local/lib/python3.9/site-packages/discord/client.py", line 343, in _run_event
    await coro(*args, **kwargs)
  File "/home/pi/bots/discord_bot/cogs/activities.py", line 84, in on_voice_state_update
    player = vc.FFmpegOpusAudio(url, after=lambda: print('done'))
AttributeError: 'VoiceClient' object has no attribute 'FFmpegOpusAudio'
Ignoring exception in on_voice_state_update
Traceback (most recent call last):
  File "/home/pi/.local/lib/python3.9/site-packages/discord/client.py", line 343, in _run_event
    await coro(*args, **kwargs)
  File "/home/pi/bots/discord_bot/cogs/activities.py", line 84, in on_voice_state_update
    player = vc.FFmpegOpusAudio(url, after=lambda: print('done'))
AttributeError: 'VoiceClient' object has no attribute 'FFmpegOpusAudio'
Ignoring exception in on_voice_state_update
Traceback (most recent call last):
  File "/home/pi/.local/lib/python3.9/site-packages/discord/client.py", line 343, in _run_event
    await coro(*args, **kwargs)
  File "/home/pi/bots/discord_bot/cogs/activities.py", line 84, in on_voice_state_update
    player = vc.FFmpegOpusAudio(url, after=lambda: print('done'))
AttributeError: 'VoiceClient' object has no attribute 'FFmpegOpusAudio'
Ignoring exception in on_voice_state_update
Traceback (most recent call last):
  File "/home/pi/.local/lib/python3.9/site-packages/discord/client.py", line 343, in _run_event
    await coro(*args, **kwargs)
  File "/home/pi/bots/discord_bot/cogs/activities.py", line 23, in on_voice_state_update
    voice_channel = member.voice.channel
AttributeError: 'NoneType' object has no attribute 'channel'
Ignoring exception in on_voice_state_update
Traceback (most recent call last):
  File "/home/pi/.local/lib/python3.9/site-packages/discord/client.py", line 343, in _run_event
    await coro(*args, **kwargs)
  File "/home/pi/bots/discord_bot/cogs/activities.py", line 84, in on_voice_state_update
    player = vc.FFmpegOpusAudio(url, after=lambda: print('done'))
AttributeError: 'VoiceClient' object has no attribute 'FFmpegOpusAudio'
Ignoring exception in on_voice_state_update
Traceback (most recent call last):
  File "/home/pi/.local/lib/python3.9/site-packages/discord/client.py", line 343, in _run_event
    await coro(*args, **kwargs)
  File "/home/pi/bots/discord_bot/cogs/activities.py", line 23, in on_voice_state_update
    voice_channel = member.voice.channel
AttributeError: 'NoneType' object has no attribute 'channel'
Ignoring exception in on_voice_state_update
Traceback (most recent call last):
  File "/home/pi/.local/lib/python3.9/site-packages/discord/client.py", line 343, in _run_event
    await coro(*args, **kwargs)
  File "/home/pi/bots/discord_bot/cogs/activities.py", line 84, in on_voice_state_update
    player = vc.FFmpegOpusAudio(url, after=lambda: print('done'))
AttributeError: 'VoiceClient' object has no attribute 'FFmpegOpusAudio'
Ignoring exception in on_voice_state_update
Traceback (most recent call last):
  File "/home/pi/.local/lib/python3.9/site-packages/discord/client.py", line 343, in _run_event
    await coro(*args, **kwargs)
  File "/home/pi/bots/discord_bot/cogs/activities.py", line 23, in on_voice_state_update
    voice_channel = member.voice.channel
AttributeError: 'NoneType' object has no attribute 'channel'
Ignoring exception in on_voice_state_update
Traceback (most recent call last):
  File "/home/pi/.local/lib/python3.9/site-packages/discord/client.py", line 343, in _run_event
    await coro(*args, **kwargs)
  File "/home/pi/bots/discord_bot/cogs/activities.py", line 23, in on_voice_state_update
    voice_channel = member.voice.channel
AttributeError: 'NoneType' object has no attribute 'channel'
Ignoring exception in on_voice_state_update
Traceback (most recent call last):
  File "/home/pi/.local/lib/python3.9/site-packages/discord/client.py", line 343, in _run_event
    await coro(*args, **kwargs)
  File "/home/pi/bots/discord_bot/cogs/activities.py", line 23, in on_voice_state_update
    voice_channel = member.voice.channel
AttributeError: 'NoneType' object has no attribute 'channel'
Ignoring exception in on_voice_state_update
Traceback (most recent call last):
  File "/home/pi/.local/lib/python3.9/site-packages/discord/client.py", line 343, in _run_event
    await coro(*args, **kwargs)
  File "/home/pi/bots/discord_bot/cogs/activities.py", line 23, in on_voice_state_update
    voice_channel = member.voice.channel
AttributeError: 'NoneType' object has no attribute 'channel'
FrozenCheerios joined Pernis
somethin else happened
13quik started streaming
groskhul joined Pernis
somethin else happened
groskhul joined Pernis
13quik joined Pernis
somethin else happened
13quik started streaming
somethin else happened
somethin else happened
13quik started streaming
FrozenCheerios joined Pernis
somethin else happened
somethin else happened
13quik started streaming
somethin else happened
somethin else happened
13quik started streaming
somethin else happened
Bot StepBot joined Pernis
Bot StepBot joined Pernis
Bot StepBot joined Pernis
Bot StepBot joined Pernis
Bot StepBot joined Pernis
Bot StepBot joined Pernis
Bot StepBot joined Pernis
Bot StepBot joined Pernis
Bot StepBot joined Pernis
Bot StepBot joined Pernis
Bot StepBot joined Pernis
13quik joined Pernis
FrozenCheerios joined Pernis
somethin else happened
13quik started streaming
somethin else happened
Bot StepBot joined Pernis
Bot StepBot joined Pernis
Bot StepBot joined Pernis
13quik joined Pernis
Bot StepBot joined Pernis
FrozenCheerios joined Pernis
FrozenCheerios joined Pernis
somethin else happened
13quik started streaming
Lord Corbin joined Pernis
somethin else happened
FrozenCheerios joined Pernis
FrozenCheerios joined Pernis
